Workbook

Sheet #上陣
A1: UI參考
B6: HERO
B8: 兵員1(敵方) | C8: 兵員2(敵方) | D8: 兵員3(敵方) | E8: 兵員4(敵方) | F8: 兵員5(敵方)
B13: 兵員1(我方) | C13: 兵員2(我方) | D13: 兵員3(我方) | E13: 兵員4(我方) | F13: 兵員5(我方)
B14: HERO
A18: *依照敏捷依序進行攻擊；攻擊規則詳參基本說明
D62: 0.03 | E62: 12 | F62: =D62/E62 -> 0.0025 | G62: 30 | H62: =G62*F62 -> 0.075
D63: 0.22 | E63: 9 | F63: =D63/E63 -> 0.024444444 | G63: =H62/F63 -> 3.0681818 | H63: 10
D64: =1-D63-D62 -> 0.75 | E64: 10 | F64: =D64/E64 -> 0.075 | G64: =H62/F64 -> 1 | H64: 5

Sheet #基本說明
A1: 單詞規則說明
A2: 傷害公式 | B2: 傷害 = Self_Atk*Self_Atk / (Enemy_Def+Self_Atk) * (Skill_Self_SkillRate*Skill係數) * if(cri亂數決定是否爆擊true *criDamge[先定150%即可] )
A4: 帳號用
A5: S_HP | B5: 等於全體角色平均的血量；該值歸0將戰鬥失敗
A6: 戰法 | B6: 特殊技能；於回合開始時發動，自動狀態下可先進行預約；下回合如果SP符合則可施放
A7: 水晶物理防 | B7: 等於全體角色的平均防禦量；受到直接攻擊時視同水晶的物理防禦，進入戰鬥後不會收BUFF影響提升與降低
A8: 水晶魔法防 | B8: 等於全體角色的平均魔法防禦量；受到直接攻擊時視同水晶的物理防禦，進入戰鬥後不會收BUFF影響提升與降低
A11: 角色用
A12: HP | B12: 角色的HP數值(起始就全滿)，歸0時則死亡
A13: MP | B13: 角色的MP數值(起始就全滿)，需要足夠的MP量才可以施放skill1與skill2，每回合開始時自動恢復10%
A14: 普通攻擊 | B14: 一般攻擊；不消耗MP，並且如果無前方角色進行抵擋傷害時，直接傷害召喚水晶(防禦用召喚水晶為準)
A15: skill1 | B15: 將會消耗MP才能進行施放
A16: skill2 | B16: 將會消耗MP才能進行施放
A17: 移動位置 | B17: 如自身左右方沒有英雄時，可以換取位置，但會消耗一回合
A18: 重生 | B18: 所有的角色死亡都會自動依照回合數進行自動復活(HP全滿、MP全滿)
A19: 重生時間 | B19: 復活時hp與mp階滿
A22: 戰鬥用
A23: 勝利條件1=全部召喚角色死亡(小於等於0)
A24: 勝利條件2=召喚水晶HP死亡(小於等於0)
A25: SKILL中沒有填AP與AD細數時；不需要有特效，並且需要判定如有填入buff_id時則須增加該BUFF至角色身上
A26: 攻擊時；只要受擊的對方已死亡，該傷害將重新計算至召喚水晶(S_HP、水晶物理防、水晶魔法防規則)
A27: 可以把英雄 跟召喚水晶理解成前排與後排，前排的英雄可以抵擋傷害，當前排死亡時；所有遠本會打到前排的攻擊(所有5個位置都會)，都會打到後排的召喚水晶
A28: 死亡的英雄不再顯示於行動順序上；每個回合將重新排序
A29: 傷害溢出功能，當次的攻擊可以造成角色死亡時；該多餘的傷害需要直接傷害到水晶(傷害不變)
A30: 水晶直接攻擊 的 水晶直接傷害追加一個規則，就是必定造成傷害再追加100%(總共兩倍)
A31: 復活時不再透過角色hp來減少當下的s_hp
A32: element有互克關係；水剋火,火剋木,木剋水，剋制關係時造成的最終傷害增加+30%(水打火)、被剋制關係時火打水時造成的最終傷害-30%
A36: level
... A38: AGI = 起始AGI * (1 + level * 0.01) level = 0 時完全不縮放，維持原始數值
B41: 傷害(物理傷害) = Self_Atk*Self_Atk / (Enemy_Def+Self_Atk) * (Skill_Self_SkillRate*Skill係數) * if(cri亂數決定是否爆擊true * criDamge[最低150%依照後續追加] )
A44: ="(1)" -> (1)
A45: 攻擊傷害 = (Self_atk^2 / (Self_atk+enemy_def ))* Damage *IfCri
A46: ="(2)" -> (2)
A47: Damage = (1+self_damageIncrease + selfBuff_damageIncrease) * (1- enemy_damageReduce)*(1- enemyBuff_damageReduce)
A48: *戰鬥中有可能會有相對應的Buff被追加，self / enemy是帶入戰鬥時的基礎；有cuerrent要被加到1+與1- 的算式中
A49: *紅字可以直接透過slot結果帶入
A50: ="(3)" -> (3)
A51: 計算爆擊: (self_cri - enemy_criReduce ) 減後；計算爆擊率
A52: 爆擊時 : IfCri = 150% + (self_criDamage - enemy_criDamageReduce) ；()內值最小=0

Sheet #職業
O2: 指定 | P2: 攻擊數量 | Q2: 1 | R2: 2 | S2: 3 | T2: 4
P3: SSR | Q3: 4.8 | R3: 2.4 | S3: 1.6 | T3: 1.2
G4: 物理攻擊 | P4: SR | Q4: 3.8 | R4: 1.9 | S4: 1.25 | T4: 0.95
G5: 魔法攻擊 | P5: R | Q5: 3 | R5: 1.55 | S5: 1.05 | T5: 0.75
B6: R | C6: 劍士 | D6: 普攻 | E6: 110001 | J6: 劍豪
D7: 狂怒一擊 | E7: CD | F7: 對敵方1體造成3AD物攻的物理傷害，並40%附加暈眩 | J7: 狂戰士
D8: 全隊增加攻擊力 | E8: CD=2 | F8: 為全體附加攻擊上升 | J8: 神射手 | O8: 隨機 | P8: 攻擊數量 | Q8: 1 | R8: 2 | S8: 3 | T8: 4
J9: 刺客 | P9: SSR | Q9: 5 | R9: 2.5 | S9: 1.7 | T9: 1.25
C10: 戰士 | D10: 普攻 | E10: 110001 | J10: 魔導士 | P10: SR | Q10: 4 | R10: 2 | S10: 1.3 | T10: 1
D11: 重劍防禦 | E11: CD | F11: 對我方隨機2體附加3AD的護盾 | J11: 神官 | P11: R | Q11: 3.15 | R11: 1.65 | S11: 1.1 | T11: 0.8
D12: 全隊增加防禦力 | E12: CD=2 | F12: 為全體附加防禦上升
O13: 初始職業 | P13: 一階 | Q13: 二階 | R13: 三階 | S13: 四階
C14: 弓劍手 | D14: 普攻 | E14: 110001 | O14: 劍士 | Q14: 劍狂 | R14: 劍聖 | S14: 神劍使
D15: 全速攻擊 | E15: CD | F15: 對敵方2體造成1.65物攻的物理傷害，並為自身附加行動加快 | Q15: 聖戰神 | R15: 黑十字騎士 | S15: 聖痕征服者
D16: 全隊增加技能傷害 | E16: CD=2 | F16: 為全體附加技能傷害上升
O17: 戰士 | Q17: 戰將 | R17: 戰神 | S17: 不滅戰神
Q18: 重裝騎士 | R18: 鋼鐵騎士 | S18: 守護戰神
C19: 盜賊 | D19: 普攻 | E19: 110001
D20: 劇毒匕首 | E20: CD | F20: 對敵方1體造成3.1物攻的物理傷害，並附加中毒效果 | O20: 弓手 | Q20: 狙擊者 | R20: 天穹獵手 | S20: 星弦獵神
D21: 全隊增加爆擊率 | E21: CD=2 | F21: 全隊增加爆擊率上升 | Q21: 遊俠 | R21: 森林王 | S21: 萬獸獵王
C23: 魔法師 | D23: 普攻 | E23: 110011 | O23: 盜賊 | Q23: 影刃 | R23: 暗影宗師 | S23: 虛空刺客
D24: 全體點燃 | E24: CD | F24: 對敵方全體造成0.6魔攻的魔法傷害，並附加灼傷 | Q24: 遊蕩者 | R24: 暗夜獵手 | S24: 幻影宗師
D25: 全隊增加魔攻上升 | E25: CD=2 | F25: 全隊增加魔攻上升
O26: 法師 | Q26: 大魔導士 | R26: 賢者 | S26: 大賢者
Q27: 咒術師 | R27: 禁術師 | S27: 深淵術士
C28: 實習祭司 | D28: 普攻 | E28: 110011
D29: 治療 | E29: CD | F29: 對我方隨機2體3AP魔攻的HP恢復 | O29: 祭司 | Q29: 主教 | R29: 聖者 | S29: 聖女／聖王
D30: 全隊增加魔防 | E30: CD=2 | F30: 為全體附加魔防上升 | Q30: 戰鬥祭司 | R30: 神殿騎士 | S30: 聖裁者
C33: 神劍使 | D33: 迴旋打擊 | E33: 為隨機3名敵人造成<AD>的物理傷害 | O33: 劍士
D34: 天翔十字閃 | E34: 為敵方3名敵人造成<AD>物理傷害，並附加防禦下降2層 | O34: 戰士
D35: 人劍合一 | E35: 為所有#名刀附加攻擊+30%層爆率+20%，爆擊傷害+50% | O35: 弓劍手
O36: 盜賊
O37: 魔法師
O38: 實習祭司

Sheet #副本玩法
B3: 特性 | C3: 掉落機制 | D3: 掉落物 | L3: 回魔量
A4: 神格試煉 | B4: 出戰限制，隨機決定 | C4: 每場都有獎勵 | D4: 職業經驗 | E4: 轉職卷碎片 | F4: 悟性藥水(有機會獲得點數；累積制) | L4: 貫穿 | M4: 貫穿抵抗
A5: 試煉之塔 | B5: 爬塔 | C5: 每場都有獎勵 | D5: 抽卡卷 | L5: 治療量 | M5: 減療量 | N5: 恢復反轉
A6: 無限地城 | B6: 選等級；中間獲得增益到打過 | C6: 挑戰整輪,打完才有獎勵 | D6: 裝備 | E6: 武器碎片 | F6: 裝備洗鍊書 | G6: 強化石 | L6: 護盾量 | M6: 護盾量減少
A7: 殲滅任務 | B7: 多wave；要一次打過 | C7: 挑戰整輪,打完才有獎勵 | D7: 裝備 | E7: 武器碎片 | F7: 武器經驗 | G7: 寶石
A11: 帳號配點 | B11: 點數只要有固定的數字出現；會有新的個性出現
B13: int | C13: 魔攻 | D13: 技能傷害 | E13: 回魔量
B14: vit | C14: HP | D14: 防禦 | E14: 護盾量
B15: agi | C15: 技能傷害 | D15: 爆擊率 | E15: 行動值
B16: str | C16: 攻擊力 | D16: 爆傷害 | E16: 貫穿 | F16: 每1點抵銷受擊敵人的防禦1點
B17: dex | C17: 爆擊率 | D17: 爆傷害 | E17: 異常狀態抗性 | F17: ID 4000~5999的抗性機率，初始為0%
B18: spr | C18: 魔防 | D18: 魔攻 | E18: 治療量 | F18: 追加最終heal，起始為100%
A24: 起始開放 | B24: 武器轉蛋
B25: 職業
B26: 職業-天賦
A28: 主線關卡 / 帳號等級 | B28: ="1-10"&",15" -> 1-10,15 | C28: 武器升級
A29: 主線關卡 / 帳號等級 | B29: ="第一章結束"&",20" -> 第一章結束,20 | C29: 武器升星 | D29: 掛機系統
A30: 主線關卡 / 帳號等級 | B30: ="2-10"&",25" -> 2-10,25 | C30: 捕獲
A31: 主線關卡 / 帳號等級 | B31: ="第二章結束"&",30" -> 第二章結束,30 | C31: 副本-試煉之塔(推塔) | D31: 自動下一關開放
A32: 主線關卡 / 帳號等級 | B32: 46091 | C32: 神格試煉 | D32: 神格 | E32: 一般、普通、困難、惡夢(難度選擇；等級區間)
A33: 主線關卡 / 帳號等級 | B33: ="第三章結束"&",40" -> 第三章結束,40 | C33: 職業裝備 | D33: 無限地城(10~50自己切換)
A34: 主線關卡 / 帳號等級 | B34: ="第四章結束"&",50" -> 第四章結束,50 | C34: 轉職
A35: 主線關卡 / 帳號等級 | B35: ="5-10"&",2轉30" -> 5-10,2轉30 | C35: 魔法石
A36: 主線關卡 / 帳號等級 | B36: ="第5章結束"&",40" -> 第5章結束,40 | C36: 副本-殲滅任務(多wave)
A37: 主線關卡 / 帳號等級 | B37: ="第7章結束"&",50" -> 第7章結束,50 | C37: 無限地城(10~130自己切換) | D37: 無限地城(50~100自己切換)
B41: 主線(一般) | C41: 50鑽石
B42: 主線(BOSS節點) | C42: 1000鑽石
B43: 副本-試煉之塔(推塔)

Sheet #向性
S1: 星0 | T1: 星1 | U1: 星2 | V1: 星3 | W1: 星4 | X1: 星5 | Y1: 星6 | Z1: 星7 | AA1: 星8 | AB1: 星9 | AC1: 星10
H2: 3 | J2: 對象 | K2: 隨機 | L2: 攻擊係數 | S2: - | T2: ★ | U2: ★★ | V2: ★★★ | W2: ★★★★ | X2: ★★★★★ | Y2: ☆★★★★ | Z2: ☆☆★★★ | AA2: ☆☆☆★★ | AB2: ☆☆☆☆★ | AC2: ☆☆☆☆☆
A3: ="58,17,13,3,6,18" -> 58,17,13,3,6,18 | B3: #魔器 | C3: #魔法 | D3: #輸出 | E3: #毀天滅地 | F3: #元素狂襲 | G3: #灼熱 | H3: 火之迦具土神劍 | I3: SSR | J3: 2 | L3: 2.4 | M3: 業火一閃 | O3: 日本神話中，素盞鳴尊斬殺火神迦具土時所用的十拳劍（亦稱羽羽斬），本身便與烈火、神血及斬擊淬鍊息息相關。 | P3: *群體最強 | S3: 對隨機敵方2體造成<AP>魔攻的魔法傷害，並40%機率附加灼傷 | T3: 灼傷發動機率+10% | U3: 灼傷發動機率+20% | V3: 攻擊對象改為4體 | W3: 灼傷發動機率+30% | X3: 解除受擊者護盾效果 | Y3: 該武器基礎魔攻10% | Z3: 該武器基礎追加魔攻20% | AA3: 該武器額外技能傷害10% | AB3: 該武器額外技能傷害20%、爆擊率+10% | AC3: AGI提升5
G4: #神祇恩賜 | I4: SSR | J4: 5 | L4: 1 | M4: 炎帝降世 | N4: CD:7 | S4: 對敵方全體造成傷害，並附加灼傷效果 | T4: cd-1 | U4: 自身額外附加炎帝(2回合魔攻+30%) | V4: cd-1 | W4: cd-1 | X4: 自身額外附加極•炎帝(2回合魔攻+50%，技能傷害+10%)
A5: ="58,17,13,2,23,24" -> 58,17,13,2,23,24 | B5: #名刀 | C5: #魔法 | D5: #輸出 | E5: #致命一擊 | F5: #臨寒 | G5: #自然之怒 | H5: 童子切安綱 | I5: SSR | J5: 2 | K5: 1 | L5: 2.5 | M5: 除魔霜障 | O5: 日本天下五劍之一，傳說曾用來斬殺酒吞童子的傳世太刀。 | S5: 對隨機敵方2體造成<AP>魔攻的魔法傷害，並40%機率附加凍傷 | T5: 額外魔防下降1層 | U5: 凍傷發動機率+10% | V5: 攻擊對象改為3體 | W5: 額外50%機率冰凍 | X5: 冰凍機率增加30%，並且凍傷發動機率追加30% | Y5: 該武器基礎魔攻10% | Z5: 該武器基礎追加魔攻15% | AA5: 該武器額外技能傷害10% | AB5: 該武器額外技能傷害20%、爆擊率+10% | AC5: AGI提升5
I6: SSR | J6: 3 | L6: 1.6 | M6: 神酒破鬼陣 | N6: CD:8 | S6: 對敵方3體造成傷害，並附加魔防下降3層 | T6: cd-1 | U6: 對受擊者附加凍傷效果1層 | V6: cd-1 | W6: cd-1 | X6: 對受擊者附加凍傷效果改為3層
A7: ="58,14,8,25,26" -> 58,14,8,25,26 | B7: #名刀 | C7: #恢復 | D7: #生生不息 | E7: #巧奪天工 | F7: #神祇恩賜 | H7: 村雨 | I7: SSR | J7: -2 | L7: 2.4 | M7: 萬物洗淨 | O7: 日本傳說中刀身會自帶水氣、殺人後能如雨水般洗淨血跡的妖刀。 | P7: *最強補 | S7: 為我方2體恢復<AP>魔攻的HP | T7: 為受治療的對象附加防禦上升效果2層 | U7: 為治癒的對象解除灼傷1回合 | V7: 額外附加持續回魔效果 | W7: 攻擊對象改為4體 | X7: 清除對象的所有異常狀態 | Y7: 該武器基礎魔攻10% | Z7: 該武器基礎追加魔攻15% | AA7: 該武器額外減傷10% | AB7: 該武器額外減傷20%、爆擊抗性-10% | AC7: AGI提升5
I8: SSR | J8: -5 | L8: 1 | M8: 清泉怒濤 | N8: CD:6 | S8: 對我方全體恢復hp | T8: cd-1 | U8: 額外附加攻擊上升與魔攻上升效果2層 | V8: cd-1 | W8: cd-1 | X8: 額外附加技能傷害上升與爆擊上升效果
A9: ="57,12,13,1,2,3" -> 57,12,13,1,2,3 | B9: #寶器 | C9: #物理 | D9: #輸出 | E9: #致命一擊 | F9: #疾風迅雷 | G9: #橫掃千軍 | H9: 隆基努斯之槍 | I9: SSR | J9: 4 | K9: 1 | L9: 1.25 | M9: 防禦崩解 | O9: 纏繞著佛珠以鎮壓邪氣的傳奇名刀，同為日本天下五劍之一。 | S9: 對隨機敵方4體造成<AD>物攻的物理攻擊，附加防禦下降 | T9: 追加附加爆擊下降2層 | U9: 攻擊對象改為全體 | V9: 改物防與魔防下降一次兩層 | W9: 追加附加技能傷害下降2層 | X9: 清除對象的上升狀態 | Y9: 該武器基礎魔攻10% | Z9: 該武器基礎追加魔攻15% | AA9: 該武器額外技能傷害10% | AB9: 該武器額外技能傷害20%、爆擊率+10% | AC9: AGI提升5
I10: SSR | J10: 3 | L10: 1.6 | M10: 神罰裁決 | N10: CD:7 | S10: 對敵方3體造成傷害，自身附加行動加快 | T10: cd-1 | U10: 40%機率附加麻痺效果 | V10: cd-1 | W10: cd-1 | X10: 改成100%附加麻痺
A11: ="58,12,13,3,1,2" -> 58,12,13,3,1,2 | B11: #名刀 | C11: #物理 | D11: #輸出 | E11: #橫掃千軍 | F11: #疾風迅雷 | G11: #致命一擊 | H11: 村正 | I11: SSR | J11: 1 | K11: 1 | L11: 5 | M11: 極限斬擊 | O11: 日本戰國時期象徵妖刀、極致鋒利的代表名匠鍛造。 | S11: 對敵方隨機1體造成<AD>物攻的物理攻擊，附加自身爆擊上升 | T11: 附加爆擊抗性下降 | U11: 額外附加自身行動加快 | V11: 額外附加妖刀效果(爆擊率+50%) | W11: 對象改為敵方2體 | X11: 額外獲得妖刀●滅效果(爆擊傷害+50%) | Y11: 該武器基礎物攻10% | Z11: 該武器基礎物攻15% | AA11: 該武器額外技能傷害10% | AB11: 該武器額外技能傷害20%、爆擊率+10% | AC11: AGI提升5
I12: SSR | J12: 1 | L12: 4.8 | M12: 一刀流・破勢 | N12: CD:6 | S12: 對敵方1體，附加鬼人狀態(1回合爆擊+30%) | T12: cd-1 | U12: 對敵方1體，附加極意鬼人狀態(2回合爆擊+30%，爆擊傷害+40%) | V12: cd-1 | W12: cd-1 | X12: 對象改為敵方2體
A13: ="58,18,5,8,15" -> 58,18,5,8,15 | B13: #名刀 | C13: #魔法 | D13: #黑暗侵蝕 | E13: #毀天滅地 | F13: #神祇恩賜 | G13: #守護 | H13: 天叢雲劍 | I13: SSR | J13: -2 | K13: 1 | M13: 神威退魔 | O13: 日本神話中的三神器之一，自八岐大蛇尾部取得，常與暴風、雲霧及冰冷神域相伴。 | S13: 為我方2體隨機附加傷害分擔 | T13: 額外為自身附加持續恢復 | U13: 為自身附加減少受到傷害1曾 | V13: 對象改為3體 | W13: 減少受到傷害+1曾 | X13: 額外解除凍傷 | Y13: 該武器基礎物防10% | Z13: 該武器基礎物防15% | AA13: 該武器額外減傷10% | AB13: 該武器額外減傷20%、爆擊抗性-10% | AC13: AGI提升5
I14: SSR | J14: -5 | L14: 1 | M14: 鏡花身法 | N14: CD:6 | S14: 對我方全體附加魔法護盾 | T14: cd-1 | U14: 附加減少受到傷害1曾 | V14: cd-1 | W14: cd-1 | X14: 附加減少受到傷害3曾
A15: ="58,12,11,20,1" -> 58,12,11,20,1 | B15: #名刀 | C15: #物理 | D15: #苦難共擔 | E15: #弱體 | F15: #疾風迅雷 | H15: 干將莫邪 | I15: SSR | J15: 2 | L15: 2.5 | M15: 陰月靈鋒 | O15: 中國春秋時期著名的雌雄雙劍，象徵鑄劍工藝的極致。 | S15: 為我方2體附加附加自身<AD>物攻的護盾 | T15: 附加傷害分擔 | U15: 額外為自身附加行動加快 | V15: 額外追加為自身附加傷害反射效果 | W15: 額外附加魔防上升與防禦上升效果 | X15: 傷害分擔改為3體 | Y15: 該武器基礎魔防10% | Z15: 該武器基礎追加魔防15% | AA15: 該武器額外減傷10% | AB15: 該武器額外減傷20%、爆擊抗性-10% | AC15: AGI提升5
I16: SSR | J16: 2 | K16: 1 | L16: 2.5 | M16: 魂力獻祭 | N16: CD:8 | S16: 為敵方隨機2體造成傷害，附加爆擊下降 | T16: cd-1 | U16: 附加攻擊下降效果 | V16: cd-1 | W16: cd-1 | X16: 對象改為3體，並額外附加防禦下降與魔防下降
A17: ="59,18,13,5,9,17" -> 59,18,13,5,9,17 | B17: #聖物 | C17: #魔法 | D17: #輸出 | E17: #毀天滅地 | F17: #元素狂襲 | G17: #灼熱 | H17: 埃斯卡利巴 | I17: SSR | J17: 1 | L17: 4.8 | M17: 聖劍光輝 | O17: 象徵王者權威與正統的亞瑟王之劍。 | S17: 對敵方1體造成<AP>魔攻的魔法傷害，並50%機率灼傷 | T17: 額外自身附加魔攻上升 | U17: 灼傷機率追加至100% | V17: 對象改為2體 | W17: 追加為自身附加行動加快 | X17: 對象改為3體 | Y17: 該武器基礎魔攻10% | Z17: 該武器基礎追加魔攻15% | AA17: 該武器額外技能傷害10% | AB17: 該武器額外技能傷害20%、爆擊率+10% | AC17: AGI提升5
I18: SSR | J18: -5 | L18: 1 | M18: 誓約之火 | N18: CD:5 | S18: 對我方全體附加魔攻上升2層 | T18: cd-1 | U18: 額外追加附加AP護盾 | V18: cd-1 | W18: cd-1 | X18: 額外追加附加爆傷上升2層
A19: ="60,18,15,25,26" -> 60,18,15,25,26 | B19: #寶器 | C19: #魔法 | D19: #神聖庇護 | E19: #巧奪天工 | F19: #疾風迅雷 | G19: #神祇恩賜 | H19: 布都御魂 | I19: SSR | J19: 1 | L19: 4.8 | M19: 神威震嶽 | O19: 日本神話中武甕槌神平定葦原中國所使用、具有神威的傳說之劍。 | P19: *單體最強 | S19: 對敵方1體造成<AP>魔攻的魔法傷害；並為自身附加爆擊上升 | T19: 額外附加自身行動加快 | U19: 額外自身技能傷害上升 | V19: 額外自身附加爆傷上升 | W19: 對象改2人 | X19: 爆傷上升、傷害上升、爆擊上升改為2層) | Y19: 該武器基礎物攻10% | Z19: 該武器基礎物攻15% | AA19: 該武器額外技能傷害10% | AB19: 該武器額外技能傷害20%、爆擊率+10% | AC19: AGI提升5
I20: SSR | J20: 1 | K20: 1 | L20: 5 | M20: 震天雷霆斬 | N20: CD:4 | S20: 對敵方隨機1體造成3次，40%自身附加攻擊上升 | T20: cd-1 | U20: 任意攻擊改為4次 | V20: cd-1 | W20: cd-1 | X20: 任意攻擊改為6次
A21: ="61,18,5,9,20" -> 61,18,5,9,20 | B21: #魔器 | C21: #物理 | D21: #毀天滅地 | E21: #元素狂襲 | F21: #黑暗侵蝕 | G21: #弱體 | H21: 提爾鋒 | I21: SSR | J21: 1 | L21: 4.8 | M21: 血祭詛咒 | O21: 北歐神話中出鞘必見血、帶來死亡詛咒的魔劍。 | S21: 對敵方1體造成<AD>物攻的物理傷害，造成40%裂傷 | T21: 額外40%附加中毒 | U21: 額外40%附加灼傷 | V21: 額外40%附加凍傷 | W21: 弱化附加機率追加至50% | X21: 弱化附加機率追加至80% | Y21: 該武器基礎物攻10% | Z21: 該武器基礎物攻15% | AA21: 該武器額外技能傷害10% | AB21: 該武器額外技能傷害20%、爆擊率+10% | AC21: AGI提升5
I22: SSR | J22: 1 | K22: 1 | L22: 5 | M22: 噬魂開鋒 | N22: CD:5 | S22: 對敵方1體隨機<AD>，額外40%附加停止 | T22: cd-1 | U22: 額外40%附加暈眩 | V22: cd-1 | W22: cd-1 | X22: 對象改2人，額外40%附加麻痺
A23: ="59,12,15,10,22" -> 59,12,15,10,22 | B23: #聖物 | C23: #物理 | D23: #守護 | E23: #銅牆鐵壁 | F23: #神聖庇護 | G23: #起死回生 | H23: 真十字架 | I23: SSR | J23: -2 | L23: 2.4 | M23: 神聖庇護 | O23: 基督教信仰中耶穌受難時所釘十字架的殘片。 | P23: *最強坦 | S23: 對我2體<AD>物攻的護盾，自身死亡後3回合將自動重生 | T23: 為護盾對象附加持續回魔 | U23: 額外附加受護衛效果 | V23: 額外附加真言效果(魔攻、物攻50%、1回) | W23: 對象改為3體 | X23: 額外附加真理效果(技能傷害10%、2回) | Y23: 該武器基礎物防10% | Z23: 該武器基礎追加物防15% | AA23: 該武器額外減傷10% | AB23: 該武器額外減傷20%、爆擊抗性-10% | AC23: AGI提升5
I24: SSR | J24: 1 | L24: 4.8 | M24: 聖光衝擊 | N24: CD:6 | S24: 對敵方1體，造成40%暈眩 | T24: cd-1 | U24: 為自身附加持續回魔與持續恢復效果 | V24: cd-1 | W24: cd-1 | X24: 改成100%附加暈眩
A25: ="60,14,15,22,8" -> 60,14,15,22,8 | B25: #寶器 | C25: #恢復 | D25: #神聖庇護 | E25: #起死回生 | F25: #生生不息 | G25: #靈能壁壘 | H25: 阿斯卡隆 | I25: SSR | J25: -2 | K25: 1 | L25: 2.5 | M25: 龍血洗禮 | O25: 聖喬治斬龍時所使用的神聖寶劍。 | S25: 對我方隨機2體恢復<AP>魔攻的hp，30%機率附加聖護(減傷+20% 1回) | T25: 額外恢復對象mp50 | U25: 對象改為3體 | V25: 追加40%聖光(技能傷害抵抗50% 1回) | W25: 對象改為4體 | X25: 額外機率改為50%追加聖護、聖光、聖斬效果(爆擊率+100% 1回合) | Y25: 該武器基礎魔攻10% | Z25: 該武器基礎追加魔攻15% | AA25: 該武器額外技能傷害10% | AB25: 該武器額外技能傷害20%、爆擊率+10% | AC25: AGI提升5
I26: SSR | J26: -1 | L26: 4.8 | M26: 英雄意志 | N26: CD:7 | S26: 對我方1體hp，追加立即恢復對象mp150 | T26: cd-1 | U26: 追加30%不屈(減少受到傷害10%，爆擊傷害抵抗50% 1回) | V26: cd-1 | W26: cd-1 | X26: 對象改為2名，立即追加現在血量對象50%的現在hp
A29: ="61,18,19,5,9,7" -> 61,18,19,5,9,7 | B29: #魔器 | C29: #魔法 | D29: #黑暗侵蝕 | E29: #毀天滅地 | F29: #元素狂襲 | H29: 潘朵拉的魔盒 | O29: 釋放世間災禍與痛苦的禁忌器物。
A30: ="59,12,15,10,23,11" -> 59,12,15,10,23,11 | B30: #聖物 | C30: #物理 | D30: #守護 | E30: #銅牆鐵壁 | F30: #靈能壁壘 | G30: #苦難共擔 | H30: 尼米安之皮 | O30: 基督教傳說中刺穿耶穌基督側腹的聖槍。
A31: ="60,18,15,22,25,26" -> 60,18,15,22,25,26 | B31: #寶器 | C31: #魔法 | D31: #守護 | E31: #神聖庇護 | F31: #巧奪天工 | G31: #神祇恩賜 | H31: 八尺瓊勾玉 | O31: 希臘神話中刀槍不入的獅皮防具。
A32: ="62,18,24,9,25,26" -> 62,18,24,9,25,26 | B32: #法器 | C32: #魔法 | D32: #自然之怒 | E32: #元素狂襲 | F32: #巧奪天工 | G32: #神祇恩賜 | H32: 五行鏡 | O32: 日本神話中的三神器之一，象徵「仁」，為古老而神聖的勾玉寶器。
A33: ="61,18,9,7,25" -> 61,18,9,7,25 | B33: #魔器 | C33: #魔法 | D33: #元素狂襲 | E33: #巧奪天工 | H33: 所羅門之鑰 | O33: 東方道法中用以觀照靈體、破除幻境的鏡類法器。 | U33: 額外附加治療反轉
A34: ="59,12,15,22,10,25" -> 59,12,15,22,10,25 | B34: #聖物 | C34: #物理 | D34: #守護 | E34: #神聖庇護 | F34: #銅牆鐵壁 | G34: #巧奪天工 | H34: 降魔杵 | O34: 凱爾特神話中太陽神的光之貫穿之槍。
A35: ="58,12,15,10,20" -> 58,12,15,10,20 | B35: #名刀 | C35: #物理 | D35: #弱體 | H35: 數珠丸恆次 | O35: 象徵至高權能與驅使靈體之力的祈福寶器。
A36: ="60,18,13,5,21,9" -> 60,18,13,5,21,9 | B36: #寶器 | C36: #魔法 | D36: #輸出 | E36: #毀天滅地 | F36: #元素狂襲 | H36: 布里歐納克 | O36: 佛教密宗中用以摧毀煩惱、鎮伏妖魔的金剛法器。
H38: 27
B39: SR | C39: 級武器清單
A40: ="56,16,13,2,1" -> 56,16,13,2,1 | C40: #名刀 | D40: #物理 | E40: #輸出 | F40: #致命一擊 | G40: #疾風迅雷 | H40: 鬼丸國綱 | I40: SR | J40: 2 | L40: 1.9 | M40: 降伏之刃 | S40: 對敵方2體造成<AD>物攻的物理傷害60%額外附加自身行動加快 | T40: MP-3 | U40: MP-3 | V40: 機率追加40% | W40: MP-3 | X40: 額外為自身附加爆擊上升
I41: SR | J41: 1 | L41: 3.8 | M41: 夢魔潰散 | N41: CD:9 | S41: 對敵方1體造稱傷害並附加潰魔(降30%魔防) | T41: cd-1 | U41: cd-1 | V41: cd-1 | W41: cd-1 | X41: 額外附加防禦下降2層
A42: ="56,16,13,4,52" -> 56,16,13,4,52 | C42: #名刀 | D42: #物理 | E42: #輸出 | F42: #橫掃千軍 | G42: #神聖庇護 | H42: 阿隆戴特 | I42: SR | J42: 3 | L42: 1.25 | M42: 漣漪斬 | S42: 對3個敵方造成物理傷害並40%機率附加自身攻擊上升 | T42: MP-3 | U42: MP-3 | V42: 機率追加50% | W42: MP-3 | X42: 對象改為4個敵人
I43: SR | J43: 3 | K43: 1 | L43: 1.3 | M43: 急流連刺 | N43: CD:8 | S43: 對敵方3體隨機造成物理傷害並附加潰防(潰防；降30%物禦) | T43: cd-1 | U43: cd-1 | V43: cd-1 | W43: cd-1 | X43: 額外為自身附加攻擊上升
...

Sheet #lock

Sheet character
A1: tpye | B1: limite | C1: HP | D1: ATK | E1: MATK | F1: DEF | G1: MDEF | H1: CRI | I1: MP | J1: cri_resist | K1: AGI | L1: damage_reflect | M1: cri_damage | N1: cri_damage_resist | O1: skill_rate | P1: skill_resist | Q1: damage_increase | R1: damage_reduce | S1: mp_recove | T1: shield_rate | U1: permeate | V1: atypical_rate | W1: heal_rate
A2: int | B2: 99 | E2: 2 | O2: 0.002 | S2: 0.003
A3: vit | B3: 99 | C3: 20 | F3: 3 | T3: 0.005
A4: agi | B4: 99 | H4: 0.002 | O4: 0.004 | Q4: 0.0005
A5: str | B5: 99 | D5: 2 | Q5: 0.00025 | U5: 2
A6: dex | B6: 99 | D6: 1 | H6: 0.001 | V6: 0.0001
A7: spr | B7: 99 | E7: 1 | G7: 3 | W7: 0.004

Sheet nature
A1: nature_info | B1: int | C1: vit | D1: agi | E1: str | F1: dex | G1: spr | H1: buff_id
A2: #深思熟慮 | B2: 99 | H2: 9900
A3: #壯如巨樹 | C3: 99 | H3: =H2+1 -> 9901
A4: #高速移動 | D4: 99 | H4: =H3+1 -> 9902
A5: #力大無窮 | E5: 99 | H5: =H4+1 -> 9903
A6: #彈無虛發 | F6: 99 | H6: =H5+1 -> 9904
A7: #無限精神 | G7: 99 | H7: =H6+1 -> 9905
A8: #領悟 | B8: 20 | H8: =H7+1 -> 9906
A9: #強壯 | C9: 20 | H9: =H8+1 -> 9907
A10: #速度 | D10: 20 | H10: =H9+1 -> 9908
A11: #力量 | E11: 20 | H11: =H10+1 -> 9909
A12: #精確 | F12: 20 | H12: =H11+1 -> 9910
A13: #精神 | G13: 20 | H13: =H12+1 -> 9911
A14: #宮廷的法師 | B14: 69 | G14: 69 | H14: =H13+1 -> 9912
A15: #極意攻勢 | E15: 69 | F15: 69 | H15: =H14+1 -> 9913
A16: #防禦怪獸 | C16: 69 | G16: 69 | H16: =H15+1 -> 9914
A17: #又快又準 | D17: 99 | F17: 49 | H17: =H16+1 -> 9915

Sheet skill
A2: skill_id | B2: 技能名稱 | C2: 攻擊對象數量 | D2: 是否為隨機 | E2: 是否自身施放 | F2: 攻擊次數 | G2: AD(技能係數) | H2: AP(技能係數) | I2: AGI | J2: current_hp | K2: cooldown | L2: isrole | M2: type | N2: MP_cost | O2: MP_revocer | P2: self_add_buff_id | Q2: self_buff_rate_overwrite | R2: add_buff_id | S2: add_buff_rate_overwrite | T2: remove_buff_id | U2: remove_buff_rate_overwrite | V2: isMpDamage | W2: prefeb_atk | X2: prefeb_hit1 | Y2: prefeb_hit2 | Z2: 說明
A3: 110000 | B3: 黑暗契約 | C3: 1 | F3: 1 | Z3: 消耗一張"暗黑契約卷"對敵方1體進行契約，如契約成功戰鬥勝利新增至武器清單中。
A4: 110001 | B4: 物理攻擊 | C4: 1 | F4: 1 | G4: 1.9 | M4: phycial | Y4: slash | Z4: 對敵方造成<AD>的物理傷害
A5: 110002 | B5: 物理2體攻擊 | C5: 2 | D5: 1 | F5: 1 | G5: 0.9 | M5: phycial | Y5: slash | Z5: 對隨機2名敵方造成<AD>的物理傷害
A6: 110003 | B6: 物理群體攻擊 | C6: 3 | D6: 1 | F6: 1 | G6: 0.8 | M6: phycial | Y6: slash | Z6: 對隨機3名敵方造成<AD>的物理傷害
A7: 110004 | B7: 迴旋打擊 | C7: 3 | D7: 1 | G7: 1.7 | M7: phycial | Y7: slash | Z7: 為隨機3名敵人造成<AD>的物理傷害
A8: 110011 | B8: 魔法攻擊 | C8: 1 | F8: 1 | H8: 2.1 | M8: magic | W8: magic_throw | Y8: explode | Z8: 對敵方敵方造成<AP>的魔法傷害
A9: 110012 | B9: 魔法2體攻擊 | C9: 2 | D9: 1 | F9: 1 | H9: 1.2 | M9: magic | W9: magic_throw | Y9: explode | Z9: 對隨機2名敵方造成<AP>的魔法傷害
A10: 110013 | B10: 魔法群體攻擊 | C10: 3 | D10: 1 | F10: 1 | H10: 0.8 | M10: magic | W10: magic_throw | Y10: explode | Z10: 對隨機3名敵方造成<AP>的魔法傷害
A12: skill_id | B12: 技能名稱 | C12: 攻擊對象數量 | D12: 是否為隨機 | E12: 是否自身施放 | F12: 攻擊次數 | G12: AD(技能係數) | H12: AP(技能係數) | I12: AGI | J12: current_hp | K12: cooldown | L12: isrole | M12: type | N12: MP_cost | O12: MP_revocer | P12: self_add_buff_id | Q12: self_buff_rate_overwrite | R12: add_buff_id | S12: add_buff_rate_overwrite | T12: remove_buff_id | U12: remove_buff_rate_overwrite | V12: isMpDamage | W12: prefeb_atk | X12: prefeb_hit1 | Y12: prefeb_hit2 | Z12: 說明
A13: 210001 | B13: 業火一閃 | C13: 2 | F13: 1 | H13: 2.4 | M13: magic | N13: 96 | R13: 4001 | S13: 0.4 | W13: magic_fire | X13: fire | Z13: 對隨機敵方2體造成<AP>魔攻的魔法傷害，並40%機率附加灼傷
A14: 210002 | B14: 除魔霜障 | C14: 2 | D14: 1 | F14: 1 | H14: 2.5 | M14: magic | N14: 95 | R14: 4002 | S14: 0.4 | W14: magic_throw | X14: explode | Z14: 對隨機敵方2體造成<AP>魔攻的魔法傷害，並40%機率附加凍傷
A15: 210003 | B15: 萬物洗淨 | C15: -2 | F15: 1 | H15: 2.4 | M15: heal | N15: 48 | W15: magic_throw | X15: explode | Z15: 為我方2體恢復<AP>魔攻的HP
A16: 210004 | B16: 防禦崩解 | C16: 4 | D16: 1 | F16: 1 | G16: 1.25 | M16: phycial | N16: 47 | R16: 2001 | X16: slash | Z16: 對隨機敵方4體造成<AD>物攻的物理攻擊，附加防禦下降
A17: 210005 | B17: 極限斬擊 | C17: 1 | D17: 1 | F17: 1 | G17: 5 | M17: phycial | N17: 49 | P17: 1005 | X17: slash | Z17: 對敵方隨機1體造成<AD>物攻的物理攻擊，附加自身爆擊上升
A18: 210006 | B18: 神威退魔 | C18: -2 | D18: 1 | F18: 1 | N18: 80 | R18: 1996 | X18: buff | Z18: 為我方2體隨機附加傷害分擔
A19: 210007 | B19: 陰月靈鋒 | C19: -2 | F19: 1 | H19: 2.5 | M19: shield | N19: 48 | R19: 1999 | X19: debuff | Z19: 為我方2體附加附加自身<AD>物攻的護盾
A20: 210008 | B20: 聖劍光輝 | C20: 1 | F20: 1 | H20: 4.8 | M20: magic | N20: 96 | R20: 4001 | S20: 0.5 | W20: magic_throw | X20: explode | Z20: 對敵方1體造成<AP>魔攻的魔法傷害，並50%機率灼傷
A21: 210009 | B21: 神威震嶽 | C21: 1 | F21: 1 | G21: 4.8 | M21: phycial | N21: 96 | P21: 1005 | W21: magic_throw | X21: explode | Z21: 對敵方1體造成<AD>物攻的物理傷害；並為自身附加爆擊上升
A22: 210010 | B22: 血祭詛咒 | C22: 1 | F22: 1 | G22: 4.8 | M22: phycial | N22: 48 | R22: 4003 | S22: 0.4 | X22: slash | Z22: 對敵方1體造成<AD>物攻的物理傷害，並40%附加裂傷
A23: 210011 | B23: 神聖庇護 | C23: -2 | F23: 1 | G23: 2.4 | M23: phycial | N23: 48 | R23: 1999 | X23: buff | Z23: 對我方2體<AD>物攻的護盾，自身死亡後3回合將自動重生
A24: 210012 | B24: 龍血洗禮 | C24: -2 | D24: 1 | F24: 1 | H24: 2.5 | M24: magic | N24: 99 | R24: 3004 | X24: heal | Z24: 對我方隨機2體恢復<AP>魔攻的hp，30%機率附加聖護(減傷+20% 1回)
A25: 210013 | B25: 降伏之刃 | C25: 2 | F25: 1 | G25: 1.9 | M25: phycial | N25: 38 | P25: 3003 | X25: stab | Z25: 對敵方2體造成<AD>物攻的物理傷害60%額外附加自身行動加快
A26: 210014 | B26: 漣漪斬 | C26: 3 | F26: 1 | G26: 1.25 | M26: phycial | N26: 38 | P26: 1001 | X26: stab | Z26: 對3個敵方造成<AD>物攻的物理傷害並40%機率附加自身攻擊上升
A27: 210015 | B27: 鬼魅之護 | C27: -2 | F27: 1 | H27: 1.9 | M27: heal | N27: 76 | R27: 1999 | X27: heal | Z27: 對我方2體恢復<AP>魔攻的HP
A28: =A27+1 -> 210016 | B28: 混沌光束 | C28: 3 | D28: 1 | F28: 1 | H28: 1.3 | M28: magic | N28: 78 | X28: explode | Z28: 為敵方隨機3體造成<AP>魔攻的魔法傷害
A29: =A28+1 -> 210017 | B29: 光華折射 | C29: -1 | D29: 1 | F29: 1 | H29: 3.8 | M29: heal | N29: 38 | R29: 1002 | X29: heal | Z29: 對我方隨機1體恢復<AP>魔攻的HP，並額外附加防禦上升效果
A30: =A29+1 -> 210018 | B30: 熾熱沸騰 | C30: 2 | D30: 1 | F30: 1 | H30: 2 | M30: magic | N30: 82 | R30: 4001 | S30: 0.3 | W30: magic_fire | X30: fire | Z30: 對敵方隨機2體造成<AP>魔攻的魔法傷害，並30%灼傷
A31: =A30+1 -> 210019 | B31: 閃光折躍 | C31: 3 | D31: 1 | F31: 1 | H31: 1.3 | M31: magic | N31: 77 | P31: 1007 | Q31: 0.4 | W31: magic_throw | X31: explode | Z31: 為敵方隨機3體造成<AP>魔攻的魔法傷害，40%機率為自身附加技能傷害上升
A32: =A31+1 -> 210020 | B32: 死亡凝視 | C32: 1 | D32: 1 | F32: 1 | H32: 4 | M32: magic | N32: 80 | R32: 5004 | S32: 0.4 | W32: magic_throw | X32: explode | Z32: 為敵方隨機1體造成<AP>魔攻的魔法傷害；並40%附加停止
A33: =A32+1 -> 210021 | B33: 破盾之刃 | C33: 4 | D33: 1 | F33: 1 | G33: 1 | M33: phycial | N33: 40 | T33: 1999 | U33: 0.5 | X33: stab | Z33: 為敵方隨機4體造成<AD>物攻的物理傷害，並50%機率去除護盾
A34: =A33+1 -> 210022 | B34: 重擲穿刺 | C34: 2 | F34: 1 | G34: 1.55 | M34: phycial | N34: 31 | R34: 2002 | S34: 0.5 | X34: beat | Z34: 為敵方2體造成<AD>物攻的物理傷害，並50%附加防禦下降
A35: =A34+1 -> 210023 | B35: 尖刺突落 | C35: 2 | F35: 1 | G35: 1.55 | M35: phycial | N35: 33 | R35: 4003 | S35: 0.25 | X35: beat | Z35: 為敵方2體造成<AD>物攻的物理傷害，並25%機率附加裂傷
A36: =A35+1 -> 210024 | B36: 火球術 | C36: 1 | F36: 1 | H36: 3 | M36: magic | N36: 60 | R36: 4001 | S36: 0.25 | W36: magic_throw | X36: fire | Z36: 對敵方1體造成<AP>魔攻的魔法傷害，並25%附加灼傷
A37: =A36+1 -> 210025 | B37: 枯朽之根 | C37: 2 | D37: 1 | F37: 1 | H37: 1.65 | M37: magic | N37: 66 | R37: 5001 | S37: 0.25 | W37: magic_throw | X37: explode | Z37: 對敵方隨機2體造成<AP>魔攻的魔法傷害，並25%附加麻痺
A38: =A37+1 -> 210026 | B38: 堅盾破甲 | C38: -2 | D38: 1 | F38: 1 | N38: 30 | R38: 1996 | X38: shield2 | Z38: 為我方隨機2體附加傷害分擔
A39: =A38+1 -> 210027 | B39: 弱點貫穿 | C39: 1 | F39: 1 | G39: 3 | M39: phycial | N39: 30 | R39: 1005 | S39: 0.4 | W39: throw | X39: explode | Z39: 為敵方1體造成<AD>物攻的物理傷害；並40%為自身爆擊上升
A40: =A39+1 -> 210028 | B40: 定氣神閒 | C40: -2 | D40: 1 | F40: 1 | H40: 1.65 | M40: magic | N40: 66 | X40: heal | Z40: 為我方隨機2體恢復<AP>魔攻的HP
A41: =A40+1 -> 210029 | B41: 雙重切削 | C41: 2 | D41: 1 | F41: 1 | G41: 1.65 | M41: phycial | N41: 33 | R41: 4003 | S41: 0.25 | X41: stab | Z41: 為敵方2體造成<AD>物攻的物理傷害，並25%附加裂傷
A42: =A41+1 -> 210030 | B42: 魔盾碎裂 | C42: 4 | D42: 1 | F42: 1 | H42: 0.75 | M42: magic | N42: 59 | R42: 2004 | S42: 0.25 | W42: magic_throw | X42: explode | Z42: 為敵方4體造成<AP>魔攻的魔法傷害，並25%附加魔防下降
...

Sheet buff
A1: buff_id | B1: buff名稱 | C1: buff_info | D1: #備註用 | E1: buff_exchange | F1: tag | G1: element | H1: ATK | I1: MATK | J1: DEF | K1: MDEF | L1: CRI | M1: MP | N1: cri_resist | O1: AGI | P1: damage_reflect | Q1: cri_damage | R1: cri_damage_resist | S1: skill_rate | T1: skill_resist | U1: damage_increase | V1: damage_reduce | W1: reflashAble | X1: max_stack | Y1: 持續回合數 | Z1: effective_turn | AA1: effective_currenthp_higher | AB1: effective_currenthp_lower | AC1: invisible | AD1: set_info | AE1: set_effective_count
A2: 1001 | B2: 攻擊上升 | C2: ="每層提升5%攻擊，可堆疊，最多"&X2&"層，持續"&Y2&"回合" -> 每層提升5%攻擊，可堆疊，最多5層，持續3回合 | D2: buff | H2: 0.05 | W2: =TRUE() -> TRUE | X2: 5 | Y2: 3
A3: 1002 | B3: 防禦上升 | C3: ="每層提升5%防禦，可堆疊，最多"&X3&"層，持續"&Y3&"回合" -> 每層提升5%防禦，可堆疊，最多5層，持續3回合 | D3: buff | J3: 0.05 | W3: =TRUE() -> TRUE | X3: 5 | Y3: 3
A4: 1003 | B4: 魔攻上升 | C4: ="每層提升5%魔攻，可堆疊，最多"&X4&"層，持續"&Y4&"回合" -> 每層提升5%魔攻，可堆疊，最多5層，持續3回合 | D4: buff | I4: 0.05 | W4: =TRUE() -> TRUE | X4: 5 | Y4: 3
A5: 1004 | B5: 魔防上升 | C5: ="每層提升5%魔防，可堆疊，最多"&X5&"層，持續"&Y5&"回合" -> 每層提升5%魔防，可堆疊，最多5層，持續3回合 | D5: buff | K5: 0.05 | W5: =TRUE() -> TRUE | X5: 5 | Y5: 3
A6: 1005 | B6: 爆擊上升 | C6: ="每層提升5%爆擊率，可堆疊，最多"&X6&"層，持續"&Y6&"回合" -> 每層提升5%爆擊率，可堆疊，最多5層，持續3回合 | D6: buff | L6: 0.05 | W6: =TRUE() -> TRUE | X6: 5 | Y6: 3
A7: 1006 | B7: 爆傷上升 | C7: ="每層提升5%爆擊傷害，可堆疊，最多"&X7&"層，持續"&Y7&"回合" -> 每層提升5%爆擊傷害，可堆疊，最多5層，持續3回合 | D7: buff | Q7: 0.05 | W7: =TRUE() -> TRUE | X7: 5 | Y7: 3
A8: 1007 | B8: 技能傷害上升 | C8: ="每層提升5%技能傷害，可堆疊，最多"&X8&"層，持續"&Y8&"回合" -> 每層提升5%技能傷害，可堆疊，最多5層，持續3回合 | D8: buff | S8: 0.05 | W8: =TRUE() -> TRUE | X8: 5 | Y8: 3
A9: 1008 | B9: 爆擊抗性上升 | C9: ="每層提升5%爆擊抗性，可堆疊，最多"&X9&"層，持續"&Y9&"回合" -> 每層提升5%爆擊抗性，可堆疊，最多5層，持續3回合 | D9: buff | N9: 0.05 | W9: =TRUE() -> TRUE | X9: 5 | Y9: 3
A10: 1009 | B10: 爆傷抗性上升 | C10: ="每層提升5%爆傷抗性，可堆疊，最多"&X10&"層，持續"&Y10&"回合" -> 每層提升5%爆傷抗性，可堆疊，最多5層，持續3回合 | D10: buff | R10: 0.05 | W10: =TRUE() -> TRUE | X10: 5 | Y10: 3
A11: 1010 | B11: 技能抵抗上升 | C11: ="每層提升5%技能倍率抗性，可堆疊，最多"&X11&"層，持續"&Y11&"回合" -> 每層提升5%技能倍率抗性，可堆疊，最多5層，持續3回合 | D11: buff | T11: 0.05 | W11: =TRUE() -> TRUE | X11: 5 | Y11: 3
A12: 1011 | B12: 增加造成傷害 | C12: ="每層提升3%造成傷害，可堆疊，最多"&X12&"層，持續"&Y12&"回合" -> 每層提升3%造成傷害，可堆疊，最多5層，持續3回合 | D12: buff | U12: 0.03 | W12: =TRUE() -> TRUE | X12: 5 | Y12: 3
A13: 1012 | B13: 減少受到傷害 | C13: ="每層提升3%減少受到傷害，可堆疊，最多"&X13&"層，持續"&Y13&"回合" -> 每層提升3%減少受到傷害，可堆疊，最多5層，持續3回合 | D13: buff | V13: 0.03 | W13: =TRUE() -> TRUE | X13: 5 | Y13: 3
A16: buff_id | B16: buff名稱 | C16: buff_info | D16: #備註用 | E16: buff_exchange | F16: tag | G16: element | H16: ATK | I16: MATK | J16: DEF | K16: MDEF | L16: CRI | M16: MP | N16: cri_resist | O16: AGI | P16: damage_reflect | Q16: cri_damage | R16: cri_damage_resist | S16: skill_rate | T16: skill_resist | U16: damage_increase | V16: damage_reduce | W16: reflashAble | X16: max_stack | Y16: 持續回合數 | Z16: effective_turn | AA16: effective_currenthp_higher | AB16: effective_currenthp_lower | AC16: invisible | AD16: set_info | AE16: set_effective_count
A17: 2001 | B17: 攻擊下降 | C17: ="每層降低5%攻擊，可堆疊，最多"&X17&"層，持續"&Y17&"回合" -> 每層降低5%攻擊，可堆疊，最多5層，持續3回合 | D17: debuff | H17: -0.05 | W17: =TRUE() -> TRUE | X17: 5 | Y17: 3
A18: 2002 | B18: 防禦下降 | C18: ="每層降低5%防禦，可堆疊，最多"&X18&"層，持續"&Y18&"回合" -> 每層降低5%防禦，可堆疊，最多5層，持續3回合 | D18: debuff | J18: -0.05 | W18: =TRUE() -> TRUE | X18: 5 | Y18: 3
A19: 2003 | B19: 魔攻下降 | C19: ="每層降低5%魔攻，可堆疊，最多"&X19&"層，持續"&Y19&"回合" -> 每層降低5%魔攻，可堆疊，最多5層，持續3回合 | D19: debuff | I19: -0.05 | W19: =TRUE() -> TRUE | X19: 5 | Y19: 3
A20: 2004 | B20: 魔防下降 | C20: ="每層降低5%魔防，可堆疊，最多"&X20&"層，持續"&Y20&"回合" -> 每層降低5%魔防，可堆疊，最多5層，持續3回合 | D20: debuff | K20: -0.05 | W20: =TRUE() -> TRUE | X20: 5 | Y20: 3
A21: 2005 | B21: 爆擊下降 | C21: ="每層降低5%爆擊率，可堆疊，最多"&X21&"層，持續"&Y21&"回合" -> 每層降低5%爆擊率，可堆疊，最多5層，持續3回合 | D21: debuff | L21: -0.05 | W21: =TRUE() -> TRUE | X21: 5 | Y21: 3
A22: 2006 | B22: 爆傷下降 | C22: ="每層降低5%爆擊傷害，可堆疊，最多"&X22&"層，持續"&Y22&"回合" -> 每層降低5%爆擊傷害，可堆疊，最多5層，持續3回合 | D22: debuff | Q22: -0.05 | W22: =TRUE() -> TRUE | X22: 5 | Y22: 3
A23: 2007 | B23: 技能傷害下降 | C23: ="每層降低5%技能傷害，可堆疊，最多"&X23&"層，持續"&Y23&"回合" -> 每層降低5%技能傷害，可堆疊，最多5層，持續3回合 | D23: debuff | S23: -0.05 | W23: =TRUE() -> TRUE | X23: 5 | Y23: 3
A24: 2008 | B24: 爆擊抗性下降 | C24: ="每層降低5%爆擊抗性，可堆疊，最多"&X24&"層，持續"&Y24&"回合" -> 每層降低5%爆擊抗性，可堆疊，最多5層，持續3回合 | D24: debuff | N24: -0.05 | W24: =TRUE() -> TRUE | X24: 5 | Y24: 3
A25: 2009 | B25: 爆傷抗性下降 | C25: ="每層降低5%爆傷抗性，可堆疊，最多"&X25&"層，持續"&Y25&"回合" -> 每層降低5%爆傷抗性，可堆疊，最多5層，持續3回合 | D25: debuff | R25: -0.05 | W25: =TRUE() -> TRUE | X25: 5 | Y25: 3
A26: 2010 | B26: 技能抵抗下降 | C26: ="每層降低5%技能傷害，可堆疊，最多"&X26&"層，持續"&Y26&"回合" -> 每層降低5%技能傷害，可堆疊，最多5層，持續3回合 | D26: debuff | T26: -0.05 | W26: =TRUE() -> TRUE | X26: 5 | Y26: 3
A27: 2011 | B27: 減少造成傷害 | C27: ="每層降低3%造成傷害，可堆疊，最多"&X27&"層，持續"&Y27&"回合" -> 每層降低3%造成傷害，可堆疊，最多5層，持續3回合 | D27: debuff | U27: -0.03 | W27: =TRUE() -> TRUE | X27: 5 | Y27: 3
A28: 2012 | B28: 增加受到傷害 | C28: ="每層增加3%受到傷害，可堆疊，最多"&X28&"層，持續"&Y28&"回合" -> 每層增加3%受到傷害，可堆疊，最多5層，持續3回合 | D28: debuff | V28: -0.03 | W28: =TRUE() -> TRUE | X28: 5 | Y28: 3
A30: buff_id | B30: buff名稱 | C30: buff_info | D30: #備註用 | E30: buff_exchange | F30: tag | G30: element | H30: ATK | I30: MATK | J30: DEF | K30: MDEF | L30: CRI | M30: MP | N30: cri_resist | O30: AGI | P30: damage_reflect | Q30: cri_damage | R30: cri_damage_resist | S30: skill_rate | T30: skill_resist | U30: damage_increase | V30: damage_reduce | W30: reflashAble | X30: max_stack | Y30: 持續回合數 | Z30: effective_turn | AA30: effective_currenthp_higher | AB30: effective_currenthp_lower | AC30: invisible | AD30: set_info | AE30: set_effective_count
A31: 1996 | B31: 傷害分擔 | C31: ="將所有受到的傷害50%改由發起護衛者承擔"&"持續"&Y31&"回合" -> 將所有受到的傷害50%改由發起護衛者承擔持續2回合 | D31: buff | W31: =FALSE() -> FALSE | X31: 1 | Y31: 2
A32: 1997 | B32: 傷害反彈 | C32: ="減少15%受到的傷害，並將受到傷害反射至攻擊者，"&"持續"&Y32&"回合" -> 減少15%受到的傷害，並將受到傷害反射至攻擊者，持續2回合 | D32: buff | P32: 0.15 | W32: =FALSE() -> FALSE | X32: 1 | Y32: 2
A33: 1998 | B33: 受護衛效果 | C33: ="將所有受到的傷害改由發起護衛者承擔，"&"持續"&Y33&"回合" -> 將所有受到的傷害改由發起護衛者承擔，持續1回合 | D33: buff | W33: =FALSE() -> FALSE | X33: 1 | Y33: 1
A34: 1999 | B34: 護盾 | C34: ="優先抵擋傷害的護盾HP，"&"持續"&Y34&"回合" -> 優先抵擋傷害的護盾HP，持續3回合 | D34: buff | W34: =FALSE() -> FALSE | X34: 1 | Y34: 3
A36: buff_id | B36: buff名稱 | C36: buff_info | D36: #備註用 | E36: buff_exchange | F36: tag | G36: element | H36: ATK | I36: MATK | J36: DEF | K36: MDEF | L36: CRI | M36: MP | N36: cri_resist | O36: AGI | P36: damage_reflect | Q36: cri_damage | R36: cri_damage_resist | S36: skill_rate | T36: skill_resist | U36: damage_increase | V36: damage_reduce | W36: reflashAble | X36: max_stack | Y36: 持續回合數 | Z36: effective_turn | AA36: effective_currenthp_higher | AB36: effective_currenthp_lower | AC36: invisible | AD36: set_info | AE36: set_effective_count
A37: 3001 | B37: 持續恢復 | C37: ="每回合恢復40%施術者魔法攻擊的HP恢復，"&"持續"&Y37&"回合" -> 每回合恢復40%施術者魔法攻擊的HP恢復，持續3回合 | D37: buff | I37: 0.4 | W37: =FALSE() -> FALSE | X37: 1 | Y37: 3
A38: 3002 | B38: 持續回魔 | C38: ="每回合恢復2%施術者魔法攻擊力的MP恢復，"&"持續"&Y38&"回合" -> 每回合恢復2%施術者魔法攻擊力的MP恢復，持續2回合 | D38: buff | I38: 0.02 | W38: =FALSE() -> FALSE | X38: 1 | Y38: 2
A39: 3003 | B39: 行動加快 | C39: ="回合結束時立即增加10%行動值，"&"持續"&Y39&"回合" -> 回合結束時立即增加10%行動值，持續2回合 | D39: buff | O39: 0.1 | W39: =FALSE() -> FALSE | X39: 1 | Y39: 2
A40: 3004 | B40: 聖護 | C40: 減少受到傷害20% | D40: buff | V40: 0.2 | W40: =FALSE() -> FALSE | X40: 1 | Y40: 2
A41: 3005 | B41: 潰防 | C41: 降低30%物理防禦 | D41: buff | J41: -0.3 | W41: =FALSE() -> FALSE | X41: 1 | Y41: 2
A42: 3006 | B42: 潰魔 | C42: 降低30%魔防防禦 | D42: buff | K42: -0.3 | W42: =FALSE() -> FALSE | X42: 1 | Y42: 2
A43: 3007 | B43: 鬼人 | C43: 爆擊率增加30% | D43: buff | L43: 0.3 | W43: =FALSE() -> FALSE | X43: 1 | Y43: 2
A44: 3008 | B44: 炎帝 | C44: 魔攻+30% | D44: buff | I44: 0.3 | W44: =FALSE() -> FALSE | X44: 1 | Y44: 2
...

Sheet card
A2: 角色id | B2: 角色名稱 | C2: rare | D2: type | E2: 體系 | F2: equipment_type | G2: tag | H2: resist_buff | I2: skill0_id | J2: skill1_id | K2: skill2_id | L2: element | M2: role_ addition | N2: hp | O2: atk | P2: matk | Q2: def | R2: mdef | S2: mp | T2: agi | U2: 重生回合數 | V2: #六維 | W2: capture_rate | X2: exchange_id | Y2: exchange_amount | Z2: star_refine_id | AA2: star_cost_id | AB2: star1_skill1 | AC2: star2_skill1 | AD2: star3_skill1 | AE2: star4_skill1 | AF2: star5_skill1 | AG2: star1_skill2 | AH2: star2_skill2 | AI2: star3_skill2 | AJ2: star4_skill2 | AK2: star5_skill2
A3: 10001 | B3: 火之迦具土 | C3: SSR | D3: weapon | F3: ="1,1" -> 1,1 | G3: ="56,58,17,13,3,6,18" -> 56,58,17,13,3,6,18 | I3: 110012 | J3: =A3+200000 -> 210001 | K3: =J3+100000 -> 310001 | L3: 2 | N3: 660 | O3: 14 | P3: 97 | Q3: 32 | R3: 55 | S3: 179 | T3: 19 | V3: =N3*0.5+O3+P3+Q3+R3+S3+T3*5 -> 802 | X3: 9101 | Y3: =IF(C3="SSR",30,IF(C3="SR",10,IF(C3="R",5))) -> 30 | Z3: =IF(C3="SSR",IF(P3>O3,"901","900"),IF(C3="SR",IF(P3>O3,"902","903" ),IF(C3="R",IF(P3>O3,"904","905" )))) -> 901 | AA3: 900 | AB3: =J3+1000 -> 211001 | AC3: =AB3+1000 -> 212001 | AD3: =AC3+1000 -> 213001 | AE3: =AD3+1000 -> 214001 | AF3: =AE3+1000 -> 215001 | AG3: =K3+1000 -> 311001 | AH3: =AG3+1000 -> 312001 | AI3: =AH3+1000 -> 313001 | AJ3: =AI3+1000 -> 314001 | AK3: =AJ3+1000 -> 315001
A4: =A3+1 -> 10002 | B4: 童子切安綱 | C4: SSR | D4: weapon | F4: ="1,1" -> 1,1 | G4: ="56,58,17,13,2,23,24" -> 56,58,17,13,2,23,24 | I4: 110011 | J4: =A4+200000 -> 210002 | K4: =J4+100000 -> 310002 | L4: 1 | N4: 700 | O4: 16 | P4: 85 | Q4: 37 | R4: 65 | S4: 248 | T4: 17 | V4: =N4*0.5+O4+P4+Q4+R4+S4+T4*5 -> 886 | X4: 9102 | Y4: =IF(C4="SSR",30,IF(C4="SR",10,IF(C4="R",5))) -> 30 | Z4: =IF(C4="SSR",IF(P4>O4,"901","900"),IF(C4="SR",IF(P4>O4,"902","903" ),IF(C4="R",IF(P4>O4,"904","905" )))) -> 901 | AA4: 900 | AB4: =AB3+1 -> 211002 | AC4: =AC3+1 -> 212002 | AD4: =AD3+1 -> 213002 | AE4: =AE3+1 -> 214002 | AF4: =AF3+1 -> 215002 | AG4: =AG3+1 -> 311002 | AH4: =AH3+1 -> 312002 | AI4: =AI3+1 -> 313002 | ... AK4: =AK3+1 -> 315002
A5: =A4+1 -> 10003 | B5: 村雨 | C5: SSR | D5: weapon | F5: ="1,1" -> 1,1 | G5: ="56,58,14,8,25,26" -> 56,58,14,8,25,26 | I5: 110011 | J5: =A5+200000 -> 210003 | K5: =J5+100000 -> 310003 | L5: 1 | N5: 750 | O5: 22 | P5: 81 | Q5: 44 | R5: 43 | S5: 126 | T5: 16 | V5: =N5*0.5+O5+P5+Q5+R5+S5+T5*5 -> 771 | X5: 9103 | Y5: =IF(C5="SSR",30,IF(C5="SR",10,IF(C5="R",5))) -> 30 | Z5: =IF(C5="SSR",IF(P5>O5,"901","900"),IF(C5="SR",IF(P5>O5,"902","903" ),IF(C5="R",IF(P5>O5,"904","905" )))) -> 901 | AA5: 900 | AB5: =AB4+1 -> 211003 | AC5: =AC4+1 -> 212003 | AD5: =AD4+1 -> 213003 | AE5: =AE4+1 -> 214003 | AF5: =AF4+1 -> 215003 | AG5: =AG4+1 -> 311003 | AH5: =AH4+1 -> 312003 | AI5: =AI4+1 -> 313003 | ... AK5: =AK4+1 -> 315003
A6: =A5+1 -> 10004 | B6: 隆基努斯槍 | C6: SSR | D6: weapon | F6: ="1,1" -> 1,1 | G6: 57,12,13,1,2,3 | I6: 110002 | J6: =A6+200000 -> 210004 | K6: =J6+100000 -> 310004 | L6: 3 | N6: 680 | O6: 91 | P6: 12 | Q6: 58 | R6: 40 | S6: 124 | T6: 15 | V6: =N6*0.5+O6+P6+Q6+R6+S6+T6*5 -> 740 | X6: 9104 | Y6: =IF(C6="SSR",30,IF(C6="SR",10,IF(C6="R",5))) -> 30 | Z6: =IF(C6="SSR",IF(P6>O6,"901","900"),IF(C6="SR",IF(P6>O6,"902","903" ),IF(C6="R",IF(P6>O6,"904","905" )))) -> 900 | AA6: 900 | AB6: =AB5+1 -> 211004 | AC6: =AC5+1 -> 212004 | AD6: =AD5+1 -> 213004 | AE6: =AE5+1 -> 214004 | AF6: =AF5+1 -> 215004 | AG6: =AG5+1 -> 311004 | AH6: =AH5+1 -> 312004 | AI6: =AI5+1 -> 313004 | ... AK6: =AK5+1 -> 315004
A7: =A6+1 -> 10005 | B7: 村正 | C7: SSR | D7: weapon | F7: ="1,1" -> 1,1 | G7: ="56,58,12,13,3,1,2" -> 56,58,12,13,3,1,2 | I7: 110001 | J7: =A7+200000 -> 210005 | K7: =J7+100000 -> 310005 | L7: 2 | N7: 690 | O7: 88 | P7: 21 | Q7: 62 | R7: 49 | S7: 126 | T7: 17 | V7: =N7*0.5+O7+P7+Q7+R7+S7+T7*5 -> 776 | X7: 9105 | Y7: =IF(C7="SSR",30,IF(C7="SR",10,IF(C7="R",5))) -> 30 | Z7: =IF(C7="SSR",IF(P7>O7,"901","900"),IF(C7="SR",IF(P7>O7,"902","903" ),IF(C7="R",IF(P7>O7,"904","905" )))) -> 900 | AA7: 900 | AB7: =AB6+1 -> 211005 | AC7: =AC6+1 -> 212005 | AD7: =AD6+1 -> 213005 | AE7: =AE6+1 -> 214005 | AF7: =AF6+1 -> 215005 | AG7: =AG6+1 -> 311005 | AH7: =AH6+1 -> 312005 | AI7: =AI6+1 -> 313005 | ... AK7: =AK6+1 -> 315005
A8: =A7+1 -> 10006 | B8: 天叢雲劍 | C8: SSR | D8: weapon | F8: ="1,1" -> 1,1 | G8: ="56,58,18,5,8,15" -> 56,58,18,5,8,15 | I8: 110012 | J8: =A8+200000 -> 210006 | K8: =J8+100000 -> 310006 | L8: 1 | N8: 930 | O8: 13 | P8: 59 | Q8: 59 | R8: 75 | S8: 231 | T8: 13 | V8: =N8*0.5+O8+P8+Q8+R8+S8+T8*5 -> 967 | X8: 9106 | Y8: =IF(C8="SSR",30,IF(C8="SR",10,IF(C8="R",5))) -> 30 | Z8: =IF(C8="SSR",IF(P8>O8,"901","900"),IF(C8="SR",IF(P8>O8,"902","903" ),IF(C8="R",IF(P8>O8,"904","905" )))) -> 901 | AA8: 900 | AB8: =AB7+1 -> 211006 | AC8: =AC7+1 -> 212006 | AD8: =AD7+1 -> 213006 | AE8: =AE7+1 -> 214006 | AF8: =AF7+1 -> 215006 | AG8: =AG7+1 -> 311006 | AH8: =AH7+1 -> 312006 | AI8: =AI7+1 -> 313006 | ... AK8: =AK7+1 -> 315006
A9: =A8+1 -> 10007 | B9: 干將莫邪 | C9: SSR | D9: weapon | F9: ="1,1" -> 1,1 | G9: ="58,12,11,20,1" -> 58,12,11,20,1 | I9: 110011 | J9: =A9+200000 -> 210007 | K9: =J9+100000 -> 310007 | L9: 3 | N9: 820 | O9: 71 | P9: 22 | Q9: 66 | R9: 55 | S9: 199 | T9: 13 | V9: =N9*0.5+O9+P9+Q9+R9+S9+T9*5 -> 888 | X9: 9107 | Y9: =IF(C9="SSR",30,IF(C9="SR",10,IF(C9="R",5))) -> 30 | Z9: =IF(C9="SSR",IF(P9>O9,"901","900"),IF(C9="SR",IF(P9>O9,"902","903" ),IF(C9="R",IF(P9>O9,"904","905" )))) -> 900 | AA9: 900 | AB9: =AB8+1 -> 211007 | AC9: =AC8+1 -> 212007 | AD9: =AD8+1 -> 213007 | AE9: =AE8+1 -> 214007 | AF9: =AF8+1 -> 215007 | AG9: =AG8+1 -> 311007 | AH9: =AH8+1 -> 312007 | AI9: =AI8+1 -> 313007 | ... AK9: =AK8+1 -> 315007
A10: 10008 | B10: 埃斯卡利巴 | C10: SSR | D10: weapon | F10: ="1,1" -> 1,1 | G10: 59,18,13,5,9,17 | I10: 110012 | J10: 210008 | K10: 310008 | L10: 3 | N10: 640 | O10: 19 | P10: 89 | Q10: 41 | R10: 55 | S10: 242 | T10: 14 | V10: =N10*0.5+O10+P10+Q10+R10+S10+T10*5 -> 836 | X10: 9108 | Y10: =IF(C10="SSR",30,IF(C10="SR",10,IF(C10="R",5))) -> 30 | Z10: =IF(C10="SSR",IF(P10>O10,"901","900"),IF(C10="SR",IF(P10>O10,"902","903" ),IF(C10="R",IF(P10>O10,"904","905" )))) -> 901 | AA10: 900 | AB10: =AB9+1 -> 211008 | AC10: =AC9+1 -> 212008 | AD10: =AD9+1 -> 213008 | AE10: =AE9+1 -> 214008 | AF10: =AF9+1 -> 215008 | AG10: =AG9+1 -> 311008 | AH10: =AH9+1 -> 312008 | AI10: =AI9+1 -> 313008 | ... AK10: =AK9+1 -> 315008
A11: 10009 | B11: 布都御魂 | C11: SSR | D11: weapon | F11: ="1,1" -> 1,1 | G11: ="56,60,18,15,25,26" -> 56,60,18,15,25,26 | I11: 110001 | J11: 210009 | K11: 310009 | L11: 1 | N11: 655 | O11: 93 | P11: 13 | Q11: 58 | R11: 40 | S11: 155 | T11: 19 | V11: =N11*0.5+O11+P11+Q11+R11+S11+T11*5 -> 781.5 | X11: 9109 | Y11: =IF(C11="SSR",30,IF(C11="SR",10,IF(C11="R",5))) -> 30 | Z11: =IF(C11="SSR",IF(P11>O11,"901","900"),IF(C11="SR",IF(P11>O11,"902","903" ),IF(C11="R",IF(P11>O11,"904","905" )))) -> 900 | AA11: 900 | AB11: =AB10+1 -> 211009 | AC11: =AC10+1 -> 212009 | AD11: =AD10+1 -> 213009 | AE11: =AE10+1 -> 214009 | AF11: =AF10+1 -> 215009 | AG11: =AG10+1 -> 311009 | AH11: =AH10+1 -> 312009 | AI11: =AI10+1 -> 313009 | ... AK11: =AK10+1 -> 315009
A12: 10010 | B12: 提爾鋒 | C12: SSR | D12: weapon | F12: ="1,1" -> 1,1 | G12: 61,18,5,9,20 | I12: 110001 | J12: 210010 | K12: 310010 | L12: 2 | N12: 680 | O12: 87 | P12: 22 | Q12: 59 | R12: 48 | S12: 192 | T12: 12 | V12: =N12*0.5+O12+P12+Q12+R12+S12+T12*5 -> 808 | X12: 9110 | Y12: =IF(C12="SSR",30,IF(C12="SR",10,IF(C12="R",5))) -> 30 | Z12: =IF(C12="SSR",IF(P12>O12,"901","900"),IF(C12="SR",IF(P12>O12,"902","903" ),IF(C12="R",IF(P12>O12,"904","905" )))) -> 900 | AA12: 900 | AB12: =AB11+1 -> 211010 | AC12: =AC11+1 -> 212010 | AD12: =AD11+1 -> 213010 | AE12: =AE11+1 -> 214010 | AF12: =AF11+1 -> 215010 | AG12: =AG11+1 -> 311010 | AH12: =AH11+1 -> 312010 | AI12: =AI11+1 -> 313010 | ... AK12: =AK11+1 -> 315010
A13: 10011 | B13: 真十字架 | C13: SSR | D13: weapon | F13: ="1,1" -> 1,1 | G13: 59,12,15,10,22 | I13: 110001 | J13: 210011 | K13: 310011 | L13: 1 | N13: 930 | O13: 61 | P13: 13 | Q13: 77 | R13: 57 | S13: 120 | T13: 11 | U13: 3 | V13: =N13*0.5+O13+P13+Q13+R13+S13+T13*5 -> 848 | X13: 9111 | Y13: =IF(C13="SSR",30,IF(C13="SR",10,IF(C13="R",5))) -> 30 | Z13: =IF(C13="SSR",IF(P13>O13,"901","900"),IF(C13="SR",IF(P13>O13,"902","903" ),IF(C13="R",IF(P13>O13,"904","905" )))) -> 900 | AA13: 900 | AB13: =AB12+1 -> 211011 | AC13: =AC12+1 -> 212011 | AD13: =AD12+1 -> 213011 | AE13: =AE12+1 -> 214011 | AF13: =AF12+1 -> 215011 | AG13: =AG12+1 -> 311011 | AH13: =AH12+1 -> 312011 | AI13: =AI12+1 -> 313011 | ... AK13: =AK12+1 -> 315011
A14: 10012 | B14: 阿斯卡隆 | C14: SSR | D14: weapon | F14: ="1,1" -> 1,1 | G14: 60,14,15,22,8 | I14: 110012 | J14: 210012 | K14: 310012 | L14: 1 | N14: 690 | O14: 16 | P14: 79 | Q14: 49 | R14: 57 | S14: 191 | T14: 13 | V14: =N14*0.5+O14+P14+Q14+R14+S14+T14*5 -> 802 | X14: 9112 | Y14: =IF(C14="SSR",30,IF(C14="SR",10,IF(C14="R",5))) -> 30 | Z14: =IF(C14="SSR",IF(P14>O14,"901","900"),IF(C14="SR",IF(P14>O14,"902","903" ),IF(C14="R",IF(P14>O14,"904","905" )))) -> 901 | AA14: 900 | AB14: =AB13+1 -> 211012 | AC14: =AC13+1 -> 212012 | AD14: =AD13+1 -> 213012 | AE14: =AE13+1 -> 214012 | AF14: =AF13+1 -> 215012 | AG14: =AG13+1 -> 311012 | AH14: =AH13+1 -> 312012 | AI14: =AI13+1 -> 313012 | ... AK14: =AK13+1 -> 315012
A15: 10013 | B15: 鬼丸國綱 | C15: SR | D15: weapon | F15: ="1,1" -> 1,1 | G15: 56,16,13,2,1 | I15: 110002 | J15: 210013 | K15: 310013 | L15: 2 | N15: 555 | O15: 70 | P15: 17 | Q15: 50 | R15: 39 | S15: 84 | T15: 10 | V15: =N15*0.5+O15+P15+Q15+R15+S15+T15*5 -> 587.5 | X15: 9113 | Y15: =IF(C15="SSR",30,IF(C15="SR",10,IF(C15="R",5))) -> 10 | Z15: =IF(C15="SSR",IF(P15>O15,"901","900"),IF(C15="SR",IF(P15>O15,"902","903" ),IF(C15="R",IF(P15>O15,"904","905" )))) -> 903 | AA15: 900 | AB15: =J15 -> 210013 | AC15: =AB15 -> 210013 | AD15: =AC15 -> 210013 | AE15: =AD15 -> 210013 | AF15: =AD15 -> 210013 | AG15: =K15 -> 310013 | AH15: =AG15 -> 310013 | AI15: =AH15 -> 310013 | AJ15: =AI15 -> 310013 | AK15: =AI15 -> 310013
A16: 10014 | B16: 阿隆戴特 | C16: SR | D16: weapon | F16: ="1,1" -> 1,1 | G16: 56,16,13,4,52 | I16: 110002 | J16: 210014 | K16: 310014 | L16: 3 | N16: 570 | O16: 68 | P16: 16 | Q16: 53 | R16: 31 | S16: 85 | T16: 10 | V16: =N16*0.5+O16+P16+Q16+R16+S16+T16*5 -> 588 | X16: 9114 | Y16: =IF(C16="SSR",30,IF(C16="SR",10,IF(C16="R",5))) -> 10 | Z16: =IF(C16="SSR",IF(P16>O16,"901","900"),IF(C16="SR",IF(P16>O16,"902","903" ),IF(C16="R",IF(P16>O16,"904","905" )))) -> 903 | AA16: 900 | AB16: =J16 -> 210014 | AC16: =AB16 -> 210014 | AD16: =AC16 -> 210014 | AE16: =AD16 -> 210014 | AF16: =AD16 -> 210014 | AG16: =K16 -> 310014 | AH16: =AG16 -> 310014 | AI16: =AH16 -> 310014 | AJ16: =AI16 -> 310014 | AK16: =AI16 -> 310014
A17: 10015 | B17: 哈迪斯之盔 | C17: SR | D17: weapon | F17: ="1,1" -> 1,1 | G17: 58,17,15,51,10 | I17: 110011 | J17: 210015 | K17: 310015 | L17: 1 | N17: 795 | O17: 55 | P17: 12 | Q17: 69 | R17: 51 | S17: 167 | T17: 9 | V17: =N17*0.5+O17+P17+Q17+R17+S17+T17*5 -> 796.5 | X17: 9115 | Y17: =IF(C17="SSR",30,IF(C17="SR",10,IF(C17="R",5))) -> 10 | Z17: =IF(C17="SSR",IF(P17>O17,"901","900"),IF(C17="SR",IF(P17>O17,"902","903" ),IF(C17="R",IF(P17>O17,"904","905" )))) -> 903 | AA17: 900 | AB17: =J17 -> 210015 | AC17: =AB17 -> 210015 | AD17: =AC17 -> 210015 | AE17: =AD17 -> 210015 | AF17: =AD17 -> 210015 | AG17: =K17 -> 310015 | AH17: =AG17 -> 310015 | AI17: =AH17 -> 310015 | AJ17: =AI17 -> 310015 | AK17: =AI17 -> 310015
A18: 10016 | B18: 封印之書 | C18: SR | D18: weapon | F18: ="1,1" -> 1,1 | G18: 58,17,51,20 | I18: 110011 | J18: =J17+1 -> 210016 | K18: =K17+1 -> 310016 | L18: 3 | N18: 510 | O18: 15 | P18: 69 | Q18: 32 | R18: 42 | S18: 174 | T18: 11 | V18: =N18*0.5+O18+P18+Q18+R18+S18+T18*5 -> 642 | X18: 9116 | Y18: =IF(C18="SSR",30,IF(C18="SR",10,IF(C18="R",5))) -> 10 | Z18: =IF(C18="SSR",IF(P18>O18,"901","900"),IF(C18="SR",IF(P18>O18,"902","903" ),IF(C18="R",IF(P18>O18,"904","905" )))) -> 902 | AA18: 900 | AB18: =J18 -> 210016 | AC18: =AB18 -> 210016 | AD18: =AC18 -> 210016 | AE18: =AD18 -> 210016 | AF18: =AD18 -> 210016 | AG18: =K18 -> 310016 | AH18: =AG18 -> 310016 | AI18: =AH18 -> 310016 | AJ18: =AI18 -> 310016 | AK18: =AI18 -> 310016
A19: 10017 | B19: 永恆聖鏡 | C19: SR | D19: weapon | F19: ="1,1" -> 1,1 | G19: 57,17,15,52,10 | I19: 110012 | J19: =J18+1 -> 210017 | K19: =K18+1 -> 310017 | L19: 3 | N19: 615 | O19: 12 | P19: 66 | Q19: 36 | R19: 35 | S19: 83 | T19: 12 | V19: =N19*0.5+O19+P19+Q19+R19+S19+T19*5 -> 599.5 | X19: 9117 | Y19: =IF(C19="SSR",30,IF(C19="SR",10,IF(C19="R",5))) -> 10 | Z19: =IF(C19="SSR",IF(P19>O19,"901","900"),IF(C19="SR",IF(P19>O19,"902","903" ),IF(C19="R",IF(P19>O19,"904","905" )))) -> 902 | AA19: 900 | AB19: =J19 -> 210017 | AC19: =AB19 -> 210017 | AD19: =AC19 -> 210017 | AE19: =AD19 -> 210017 | AF19: =AD19 -> 210017 | AG19: =K19 -> 310017 | AH19: =AG19 -> 310017 | AI19: =AH19 -> 310017 | AJ19: =AI19 -> 310017 | AK19: =AI19 -> 310017
A20: 10018 | B20: 熔岩之鼎 | C20: SR | D20: weapon | F20: ="1,1" -> 1,1 | G20: 57,17,13,18,53 | I20: 110012 | J20: =J19+1 -> 210018 | K20: =K19+1 -> 310018 | L20: 2 | N20: 530 | O20: 15 | P20: 57 | Q20: 32 | R20: 42 | S20: 174 | T20: 8 | V20: =N20*0.5+O20+P20+Q20+R20+S20+T20*5 -> 625 | X20: 9118 | Y20: =IF(C20="SSR",30,IF(C20="SR",10,IF(C20="R",5))) -> 10 | Z20: =IF(C20="SSR",IF(P20>O20,"901","900"),IF(C20="SR",IF(P20>O20,"902","903" ),IF(C20="R",IF(P20>O20,"904","905" )))) -> 902 | AA20: 900 | AB20: =J20 -> 210018 | AC20: =AB20 -> 210018 | AD20: =AC20 -> 210018 | AE20: =AD20 -> 210018 | AF20: =AD20 -> 210018 | AG20: =K20 -> 310018 | AH20: =AG20 -> 310018 | AI20: =AH20 -> 310018 | AJ20: =AI20 -> 310018 | AK20: =AI20 -> 310018
A21: 10019 | B21: 布里歐納克 | C21: SR | D21: weapon | F21: ="1,1" -> 1,1 | G21: 57,17,13,6,6 | I21: 110011 | J21: =J20+1 -> 210019 | K21: =K20+1 -> 310019 | L21: 1 | N21: 565 | O21: 18 | P21: 61 | Q21: 32 | R21: 42 | S21: 161 | T21: 9 | V21: =N21*0.5+O21+P21+Q21+R21+S21+T21*5 -> 641.5 | X21: 9119 | Y21: =IF(C21="SSR",30,IF(C21="SR",10,IF(C21="R",5))) -> 10 | Z21: =IF(C21="SSR",IF(P21>O21,"901","900"),IF(C21="SR",IF(P21>O21,"902","903" ),IF(C21="R",IF(P21>O21,"904","905" )))) -> 902 | AA21: 900 | AB21: =J21 -> 210019 | AC21: =AB21 -> 210019 | AD21: =AC21 -> 210019 | AE21: =AD21 -> 210019 | AF21: =AD21 -> 210019 | AG21: =K21 -> 310019 | AH21: =AG21 -> 310019 | AI21: =AH21 -> 310019 | AJ21: =AI21 -> 310019 | AK21: =AI21 -> 310019
A22: 10020 | B22: 美杜莎之盾 | C22: SR | D22: weapon | F22: ="1,1" -> 1,1 | G22: 59,17,15,20,9 | I22: 110011 | J22: =J21+1 -> 210020 | K22: =K21+1 -> 310020 | L22: 3 | N22: 730 | O22: 16 | P22: 49 | Q22: 53 | R22: 57 | S22: 153 | T22: 9 | V22: =N22*0.5+O22+P22+Q22+R22+S22+T22*5 -> 738 | X22: 9120 | Y22: =IF(C22="SSR",30,IF(C22="SR",10,IF(C22="R",5))) -> 10 | Z22: =IF(C22="SSR",IF(P22>O22,"901","900"),IF(C22="SR",IF(P22>O22,"902","903" ),IF(C22="R",IF(P22>O22,"904","905" )))) -> 902 | AA22: 900 | AB22: =J22 -> 210020 | AC22: =AB22 -> 210020 | AD22: =AC22 -> 210020 | AE22: =AD22 -> 210020 | AF22: =AD22 -> 210020 | AG22: =K22 -> 310020 | AH22: =AG22 -> 310020 | AI22: =AH22 -> 310020 | AJ22: =AI22 -> 310020 | AK22: =AI22 -> 310020
A23: 10021 | B23: 赫格尼之劍 | C23: SR | D23: weapon | F23: ="1,1" -> 1,1 | G23: 58,16,13,51,4 | I23: 110002 | J23: =J22+1 -> 210021 | K23: =K22+1 -> 310021 | L23: 1 | N23: 590 | O23: 57 | P23: 12 | Q23: 42 | R23: 27 | S23: 87 | T23: 10 | V23: =N23*0.5+O23+P23+Q23+R23+S23+T23*5 -> 570 | X23: 9121 | Y23: =IF(C23="SSR",30,IF(C23="SR",10,IF(C23="R",5))) -> 10 | Z23: =IF(C23="SSR",IF(P23>O23,"901","900"),IF(C23="SR",IF(P23>O23,"902","903" ),IF(C23="R",IF(P23>O23,"904","905" )))) -> 903 | AA23: 900 | AB23: =J23 -> 210021 | AC23: =AB23 -> 210021 | AD23: =AC23 -> 210021 | AE23: =AD23 -> 210021 | AF23: =AD23 -> 210021 | AG23: =K23 -> 310021 | AH23: =AG23 -> 310021 | AI23: =AH23 -> 310021 | AJ23: =AI23 -> 310021 | AK23: =AI23 -> 310021
A24: 10022 | B24: 堅鐵長矛 | C24: R | D24: weapon | F24: ="1,1" -> 1,1 | G24: 16,13,4 | I24: 110001 | J24: =J23+1 -> 210022 | K24: =K23+1 -> 310022 | L24: 2 | N24: 500 | O24: 48 | P24: 10 | Q24: 36 | R24: 23 | S24: 48 | T24: 8 | V24: =N24*0.5+O24+P24+Q24+R24+S24+T24*5 -> 455 | X24: 9122 | Y24: =IF(C24="SSR",30,IF(C24="SR",10,IF(C24="R",5))) -> 5 | Z24: =IF(C24="SSR",IF(P24>O24,"901","900"),IF(C24="SR",IF(P24>O24,"902","903" ),IF(C24="R",IF(P24>O24,"904","905" )))) -> 905 | AA24: 900 | AB24: =J24 -> 210022 | AC24: =AB24 -> 210022 | AD24: =AC24 -> 210022 | AE24: =AD24 -> 210022 | AF24: =AD24 -> 210022 | AG24: =K24 -> 310022 | AH24: =AG24 -> 310022 | AI24: =AH24 -> 310022 | AJ24: =AI24 -> 310022 | AK24: =AI24 -> 310022
A25: 10023 | B25: 尖刺短刀 | C25: R | D25: weapon | F25: ="1,1" -> 1,1 | G25: 16,13,2 | I25: 110002 | J25: =J24+1 -> 210023 | K25: =K24+1 -> 310023 | L25: 1 | N25: 480 | O25: 51 | P25: 12 | Q25: 33 | R25: 27 | S25: 54 | T25: 9 | V25: =N25*0.5+O25+P25+Q25+R25+S25+T25*5 -> 462 | X25: 9123 | Y25: =IF(C25="SSR",30,IF(C25="SR",10,IF(C25="R",5))) -> 5 | Z25: =IF(C25="SSR",IF(P25>O25,"901","900"),IF(C25="SR",IF(P25>O25,"902","903" ),IF(C25="R",IF(P25>O25,"904","905" )))) -> 905 | AA25: 900 | AB25: =J25 -> 210023 | AC25: =AB25 -> 210023 | AD25: =AC25 -> 210023 | AE25: =AD25 -> 210023 | AF25: =AD25 -> 210023 | AG25: =K25 -> 310023 | AH25: =AG25 -> 310023 | AI25: =AH25 -> 310023 | AJ25: =AI25 -> 310023 | AK25: =AI25 -> 310023
A26: 10024 | B26: 學徒法杖 | C26: R | D26: weapon | F26: ="1,1" -> 1,1 | G26: 61,17,6 | I26: 110011 | J26: =J25+1 -> 210024 | K26: =K25+1 -> 310024 | L26: 3 | N26: 460 | O26: 15 | P26: 55 | Q26: 19 | R26: 37 | S26: 110 | T26: 7 | V26: =N26*0.5+O26+P26+Q26+R26+S26+T26*5 -> 501 | X26: 9124 | Y26: =IF(C26="SSR",30,IF(C26="SR",10,IF(C26="R",5))) -> 5 | Z26: =IF(C26="SSR",IF(P26>O26,"901","900"),IF(C26="SR",IF(P26>O26,"902","903" ),IF(C26="R",IF(P26>O26,"904","905" )))) -> 904 | AA26: 900 | AB26: =J26 -> 210024 | AC26: =AB26 -> 210024 | AD26: =AC26 -> 210024 | AE26: =AD26 -> 210024 | AF26: =AD26 -> 210024 | AG26: =K26 -> 310024 | AH26: =AG26 -> 310024 | AI26: =AH26 -> 310024 | AJ26: =AI26 -> 310024 | AK26: =AI26 -> 310024
A27: 10025 | B27: 枯木魔杖 | C27: R | D27: weapon | F27: ="1,1" -> 1,1 | G27: 58,17,20,14,53 | I27: 110011 | J27: =J26+1 -> 210025 | K27: =K26+1 -> 310025 | L27: 2 | N27: 475 | O27: 15 | P27: 49 | Q27: 28 | R27: 39 | S27: 87 | T27: 7 | V27: =N27*0.5+O27+P27+Q27+R27+S27+T27*5 -> 490.5 | X27: 9125 | Y27: =IF(C27="SSR",30,IF(C27="SR",10,IF(C27="R",5))) -> 5 | Z27: =IF(C27="SSR",IF(P27>O27,"901","900"),IF(C27="SR",IF(P27>O27,"902","903" ),IF(C27="R",IF(P27>O27,"904","905" )))) -> 904 | AA27: 900 | AB27: =J27 -> 210025 | AC27: =AB27 -> 210025 | AD27: =AC27 -> 210025 | AE27: =AD27 -> 210025 | AF27: =AD27 -> 210025 | AG27: =K27 -> 310025 | AH27: =AG27 -> 310025 | AI27: =AH27 -> 310025 | AJ27: =AI27 -> 310025 | AK27: =AI27 -> 310025
A28: 10026 | B28: 十字堅盾 | C28: R | D28: weapon | F28: ="1,1" -> 1,1 | G28: 59,16,15,9,11 | I28: 110002 | J28: =J27+1 -> 210026 | K28: =K27+1 -> 310026 | L28: 1 | N28: 680 | O28: 44 | P28: 11 | Q28: 55 | R28: 43 | S28: 56 | T28: 6 | V28: =N28*0.5+O28+P28+Q28+R28+S28+T28*5 -> 579 | X28: 9126 | Y28: =IF(C28="SSR",30,IF(C28="SR",10,IF(C28="R",5))) -> 5 | Z28: =IF(C28="SSR",IF(P28>O28,"901","900"),IF(C28="SR",IF(P28>O28,"902","903" ),IF(C28="R",IF(P28>O28,"904","905" )))) -> 905 | AA28: 900 | AB28: =J28 -> 210026 | AC28: =AB28 -> 210026 | AD28: =AC28 -> 210026 | AE28: =AD28 -> 210026 | AF28: =AD28 -> 210026 | AG28: =K28 -> 310026 | AH28: =AG28 -> 310026 | AI28: =AH28 -> 310026 | AJ28: =AI28 -> 310026 | AK28: =AI28 -> 310026
A29: 10027 | B29: 獵人之弓 | C29: R | D29: weapon | F29: ="1,1" -> 1,1 | G29: 16,13,1 | I29: 110001 | J29: =J28+1 -> 210027 | K29: =K28+1 -> 310027 | L29: 2 | N29: 490 | O29: 51 | P29: 9 | Q29: 33 | R29: 29 | S29: 51 | T29: 10 | V29: =N29*0.5+O29+P29+Q29+R29+S29+T29*5 -> 468 | X29: 9127 | Y29: =IF(C29="SSR",30,IF(C29="SR",10,IF(C29="R",5))) -> 5 | Z29: =IF(C29="SSR",IF(P29>O29,"901","900"),IF(C29="SR",IF(P29>O29,"902","903" ),IF(C29="R",IF(P29>O29,"904","905" )))) -> 905 | AA29: 900 | AB29: =J29 -> 210027 | AC29: =AB29 -> 210027 | AD29: =AC29 -> 210027 | AE29: =AD29 -> 210027 | AF29: =AD29 -> 210027 | AG29: =K29 -> 310027 | AH29: =AG29 -> 310027 | AI29: =AH29 -> 310027 | AJ29: =AI29 -> 310027 | AK29: =AI29 -> 310027
... A33: 10031 | B33: 戰鬥者長劍 | C33: R | D33: weapon | F33: ="1,1" -> 1,1 | G33: 16,2,1 | I33: 110001 | J33: =J32+1 -> 210031 | K33: =K32+1 -> 310031 | L33: 3 | N33: 500 | O33: 49 | P33: 8 | Q33: 33 | R33: 21 | S33: 54 | T33: 9 | V33: =N33*0.5+O33+P33+Q33+R33+S33+T33*5 -> 460 | X33: 9127 | Y33: =IF(C33="SSR",30,IF(C33="SR",10,IF(C33="R",5))) -> 5 | Z33: =IF(C33="SSR",IF(P33>O33,"901","900"),IF(C33="SR",IF(P33>O33,"902","903" ),IF(C33="R",IF(P33>O33,"904","905" )))) -> 905 | AA33: 900 | AB33: =J33 -> 210031 | AC33: =AB33 -> 210031 | AD33: =AC33 -> 210031 | AE33: =AD33 -> 210031 | AF33: =AD33 -> 210031 | AG33: =K33 -> 310031 | AH33: =AG33 -> 310031 | AI33: =AH33 -> 310031 | AJ33: =AI33 -> 310031 | AK33: =AI33 -> 310031
A35: 角色id | B35: 角色名稱 | C35: rare | D35: type | E35: 體系 | F35: equipment_type | G35: tag | H35: resist_buff | I35: skill0_id | J35: skill1_id | K35: skill2_id | L35: element | M35: role_ addition | N35: HP | O35: ATK | P35: MATK | Q35: DEF | R35: MDEF | S35: MP | T35: AGI | U35: 重生回合數 | V35: #六維 | W35: capture_rate | X35: exchange_id | Y35: exchange_amount | Z35: star_refine_id | AA35: star_cost_id | AB35: star1_skill1 | AC35: star2_skill1 | AD35: star3_skill1 | AE35: star4_skill1 | AF35: star5_skill1 | AG35: star1_skill2 | AH35: star2_skill2 | AI35: star3_skill2 | AJ35: star4_skill2 | AK35: star5_skill2
A36: 90001 | B36: 劍士 | C36: R | D36: role | E36: 物攻 | F36: 2,3,4,5,6,7 | G36: 21 | H36: ="1001,1002,1003,1004,1005,2001,2002,2003,2004,2005,1997" -> 1001,1002,1003,1004,1005,2001,2002,2003,2004,2005,1997 | I36: 110001 | J36: =A36+800000 -> 890001 | K36: =J36+100000 -> 990001 | M36: ="{1.1},{1.1},{0.3},{1},{0.3}" -> {1.1},{1.1},{0.3},{1},{0.3} | N36: 500 | O36: 99 | P36: 35 | Q36: 75 | R36: 47 | T36: 9
A37: 90002 | B37: 戰士 | C37: R | D37: role | E37: 物防 | F37: 2,3,4,5,6,7 | G37: 21 | H37: ="1001,1002,1003,1004,1005,2001,2002,2003,2004,2005,1997" -> 1001,1002,1003,1004,1005,2001,2002,2003,2004,2005,1997 | I37: 110001 | J37: =A37+800000 -> 890002 | K37: =J37+100000 -> 990002 | M37: ="{1.5},{0.7},{0.3},{1.2},{1}" -> {1.5},{0.7},{0.3},{1.2},{1} | N37: 680 | O37: 80 | P37: 20 | Q37: 82 | R37: 77 | T37: 10
A38: 90003 | B38: 弓劍手 | C38: R | D38: role | E38: 物攻 | F38: 2,3,4,5,6,7 | G38: 21 | H38: ="1001,1002,1003,1004,1005,2001,2002,2003,2004,2005,1997" -> 1001,1002,1003,1004,1005,2001,2002,2003,2004,2005,1997 | I38: 110001 | J38: =A38+800000 -> 890003 | K38: =J38+100000 -> 990003 | M38: ="{0.7},{1.4},{0.3},{0.3},{0.4}" -> {0.7},{1.4},{0.3},{0.3},{0.4} | N38: 490 | O38: 99 | P38: 35 | Q38: 63 | R38: 56 | T38: 8
A39: 90004 | B39: 盜賊 | C39: R | D39: role | E39: 魔防 | F39: 2,3,4,5,6,7 | G39: 21 | H39: ="1001,1002,1003,1004,1005,2001,2002,2003,2004,2005,1997" -> 1001,1002,1003,1004,1005,2001,2002,2003,2004,2005,1997 | I39: 110001 | J39: =A39+800000 -> 890004 | K39: =J39+100000 -> 990004 | M39: ="{0.8},{1.3},{0.3},{0.3},{0.3}" -> {0.8},{1.3},{0.3},{0.3},{0.3} | N39: 475 | O39: 50 | P39: 97 | Q39: 54 | R39: 48 | T39: 8
A40: 90005 | B40: 魔法師 | C40: R | D40: role | E40: 魔攻 | F40: 2,3,4,5,6,7 | G40: 21 | H40: ="1001,1002,1003,1004,1005,2001,2002,2003,2004,2005,1997" -> 1001,1002,1003,1004,1005,2001,2002,2003,2004,2005,1997 | I40: 110011 | J40: =A40+800000 -> 890005 | K40: =J40+100000 -> 990005 | M40: ="{1},{0.3},{1.1},{1},{0.3}" -> {1},{0.3},{1.1},{1},{0.3} | N40: 475 | O40: 20 | P40: 101 | Q40: 51 | R40: 72 | T40: 10
A41: 90006 | B41: 實習祭司 | C41: R | D41: role | E41: 魔攻 | F41: 2,3,4,5,6,7 | G41: 21 | H41: ="1001,1002,1003,1004,1005,2001,2002,2003,2004,2005,1997" -> 1001,1002,1003,1004,1005,2001,2002,2003,2004,2005,1997 | I41: 110011 | J41: =A41+800000 -> 890006 | K41: =J41+100000 -> 990006 | M41: ="{1.2},{0.3},{1.1},{1},{0.3}" -> {1.2},{0.3},{1.1},{1},{0.3} | N41: 530 | O41: 35 | P41: 99 | Q41: 67 | R41: 74 | T41: 9
A42: 90007 | B42: 神劍使 | C42: SSR | D42: role | E42: 物攻 | F42: 2,3,4,5,6,7 | G42: 23 | H42: ="1001,1002,1003,1004,1005,2001,2002,2003,2004,2005,1997" -> 1001,1002,1003,1004,1005,2001,2002,2003,2004,2005,1997 | I42: 110004 | J42: =A42+800000 -> 890007 | K42: =J42+100000 -> 990007 | M42: {1.7},{1.7},{0.9},{1.6},{0.9} | N42: =ROUND(N43*1.7,0) -> 1445 | O42: =ROUND(O43*1.7,0) -> 286 | P42: =ROUND(P43*1.7,0) -> 102 | Q42: =ROUND(Q43*1.7,0) -> 218 | R42: =ROUND(R43*1.7,0) -> 136 | T42: 14
A43: =A42+1 -> 90008 | B43: 劍豪 | C43: SR | D43: role | E43: 物攻 | F43: 2,3,4,5,6,7 | G43: 22 | H43: ="1001,1002,1003,1004,1005,2001,2002,2003,2004,2005,1997" -> 1001,1002,1003,1004,1005,2001,2002,2003,2004,2005,1997 | I43: 110001 | J43: 890001 | K43: 990001 | M43: ="{1.3},{1.3},{0.5},{1.2},{0.5}" -> {1.3},{1.3},{0.5},{1.2},{0.5} | N43: =ROUND(N36*1.7,0) -> 850 | O43: =ROUND(O36*1.7,0) -> 168 | P43: =ROUND(P36*1.7,0) -> 60 | Q43: =ROUND(Q36*1.7,0) -> 128 | R43: =ROUND(R36*1.7,0) -> 80 | T43: =T36 -> 9
A44: =A43+1 -> 90009 | B44: 狂戰士 | C44: SR | D44: role | E44: 物防 | F44: 2,3,4,5,6,7 | G44: 22 | H44: ="1001,1002,1003,1004,1005,2001,2002,2003,2004,2005,1997" -> 1001,1002,1003,1004,1005,2001,2002,2003,2004,2005,1997 | I44: 110001 | J44: 890002 | K44: 990002 | M44: ="{1.7},{0.9},{0.5},{1.5},{1.2}" -> {1.7},{0.9},{0.5},{1.5},{1.2} | N44: =ROUND(N37*1.7,0) -> 1156 | O44: =ROUND(O37*1.7,0) -> 136 | P44: =ROUND(P37*1.7,0) -> 34 | Q44: =ROUND(Q37*1.7,0) -> 139 | R44: =ROUND(R37*1.7,0) -> 131 | T44: =T37 -> 10
A45: =A44+1 -> 90010 | B45: 神射手 | C45: SR | D45: role | E45: 物攻 | F45: 2,3,4,5,6,7 | G45: 22 | H45: ="1001,1002,1003,1004,1005,2001,2002,2003,2004,2005,1997" -> 1001,1002,1003,1004,1005,2001,2002,2003,2004,2005,1997 | I45: 110001 | J45: 890003 | K45: 990003 | M45: ="{0.9},{1.6},{0.5},{0.5},{0.6}" -> {0.9},{1.6},{0.5},{0.5},{0.6} | N45: =ROUND(N38*1.7,0) -> 833 | O45: =ROUND(O38*1.7,0) -> 168 | P45: =ROUND(P38*1.7,0) -> 60 | Q45: =ROUND(Q38*1.7,0) -> 107 | R45: =ROUND(R38*1.7,0) -> 95 | T45: =T38+2 -> 10
...

Sheet maplist
A2: type | B2: info | C2: begin_time | D2: end_time | E2: #備註
B3: 神格試煉 | C3: 46245.999 | D3: 46610.999 | E3: #固定玩法
A4: tower | B4: 試煉之塔 | C4: 46245.999 | D4: 46610.999
B5: 無限地城 | C5: 46245.999 | D5: 46610.999 | E5: #固定玩法
A6: annihilation | B6: 殲滅任務 | C6: 46245.999 | D6: 46610.999

Sheet mapdata
A1: mapid | B1: type | C1: chapter | D1: hint | E1: level | F1: tag_limit | G1: quest | H1: arrangement | I1: Capability | J1: event1_name | K1: event1_type | L1: event1_buff | M1: event1_time | N1: event1_target | O1: event1_rate | P1: event2_name | Q1: event2_type | R1: event2_buff | S1: event2_time | T1: event2_target | U1: event2_rate | V1: loot1_id | W1: loot1_amount | X1: loot1_rate | Y1: loot2_id | Z1: loot2_amount | AA1: loot2_rate | AB1: loot3_id | AC1: loot3_amount | AD1: loot3_rate | AE1: loot4_id | AF1: loot4_amount | AG1: loot4_rate
A3: 101 | B3: tower | D3: 第1層 | E3: 2 | G3: {role:-1}, {id:-1},{id:-1},{id:-1},{id:-1},{id:-1} {id:40082},{id:40015},{id:40004},{id:40036},{id:40032} | H3: 1 | J3: 敵方弱化 | K3: select_enemy | L3: 2002,2003,2004 | M3: 3 | N3: 1 | O3: 1 | P3: 信號干擾 | Q3: debuff | R3: 2004 | S3: 2,9,11 | T3: 0 | U3: 1 | V3: 70001 | W3: 1 | X3: 1 | Y3: 8000 | Z3: 101 | AA3: 1 | AB3: 1001 | AC3: 100 | AD3: 1
A4: 102 | B4: tower | D4: 第2層 | E4: 4 | G4: {role:-1}, {id:-1},{id:-1},{id:-1},{id:-1},{id:-1} {id:40012},{id:40076},{id:40055},{id:40005},{id:40004} | H4: 1 | J4: 信息同享 | K4: buff | L4: 1005 | M4: 4 | O4: 1 | P4: 泥濘 | Q4: debuff | R4: 2005 | S4: 9 | T4: 0 | U4: 1 | V4: 70001 | W4: 1 | X4: 1 | Y4: 8000 | Z4: 102 | AA4: 1 | AB4: 1001 | AC4: 100 | AD4: 1
A5: 103 | B5: tower | D5: 第3層 | E5: 6 | G5: {role:-1}, {id:-1},{id:-1},{id:-1},{id:-1},{id:-1} {id:40078},{id:40004},{id:40072},{id:40026},{id:40084} | H5: 1 | J5: 敵方弱化 | K5: select_enemy | L5: 2002,2003,2004 | M5: 4,7,9 | N5: 1 | O5: 1 | P5: 酸雨 | Q5: debuff | R5: 2002 | S5: 5,10 | T5: 0 | U5: 1 | V5: 70001 | W5: 1 | X5: 1 | Y5: 8000 | Z5: 103 | AA5: 1 | AB5: 1001 | AC5: 100 | AD5: 1
A6: 104 | B6: tower | D6: 第4層 | E6: 8 | G6: {role:-1}, {id:-1},{id:-1},{id:-1},{id:-1},{id:-1} {id:40001},{id:40021},{id:40055},{id:40044},{id:40036} | H6: 1 | J6: 磁場共振 | K6: buff | L6: 1003 | M6: 4 | O6: 1 | P6: 信號干擾 | Q6: debuff | R6: 2004 | S6: 2,13 | T6: 0 | U6: 1 | V6: 70001 | W6: 1 | X6: 1 | Y6: 8000 | Z6: 104 | AA6: 1 | AB6: 1001 | AC6: 100 | AD6: 1
A7: 105 | B7: tower | D7: 第5層 | E7: 10 | G7: {role:-1}, {id:-1},{id:-1},{id:-1},{id:-1},{id:-1} {id:50001},{id:40049},{id:40013},{id:40046},{id:40045} | H7: 1 | J7: 敵方弱化 | K7: select_enemy | L7: 2002,2003,2004 | M7: 1,5,8 | N7: 1 | O7: 1 | P7: 泥濘 | Q7: debuff | R7: 2005 | S7: 2,7,13 | T7: 0 | U7: 1 | V7: 70001 | W7: 1 | X7: 1 | Y7: 8000 | Z7: 105 | AA7: 1 | AB7: 1001 | AC7: 100 | AD7: 1
A8: 106 | B8: tower | D8: 第6層 | E8: 12 | G8: {role:-1}, {id:-1},{id:-1},{id:-1},{id:-1},{id:-1} {id:40071},{id:40038},{id:40081},{id:40080},{id:40047} | H8: 1 | J8: 大晴天 | K8: buff | L8: 1001 | M8: 2,4,12 | O8: 1 | P8: 酸雨 | Q8: debuff | R8: 2002 | S8: 11 | T8: 0 | U8: 1 | V8: 70001 | W8: 1 | X8: 1 | Y8: 8000 | Z8: 106 | AA8: 1 | AB8: 1001 | AC8: 100 | AD8: 1
